Workbook

Sheet Balance Sheet
B2: X GOLF AMERICA, INC.
B3: Consolidated Financial Statements
B4: Balance Sheet (unaudited)
B7: Consolidated Balance Sheet | E7: Dec. 31, 2025 | G7: Dec. 31, 2024 | I7: Dec. 31, 2023 | K7: Dec. 31, 2022 | M7: Dec. 31, 2021 | O7: Dec. 31, 2020
C8: Assets
B9: Current Assets:
C10: Cash and equivalents | E10: 4134995.1 | G10: 4088509.4 | I10: 6038305 | K10: 4116912 | M10: 3189773 | O10: 667575
C11: Accounts receivable | E11: 1456226.4 | G11: 1352017.1 | I11: 1720021 | K11: 714005 | M11: 1428090 | O11: 1180778
C12: Inventory | E12: 4269120.1 | G12: 6116857 | I12: 5075900 | K12: =3940301+46703+733290 -> 4720294 | M12: =2859267+733290 -> 3592557 | O12: 1151111
C13: Other current assets | E13: 362496.47 | G13: 348903.3 | I13: 180325 | K13: =39862+44152+21000 -> 105014 | M13: 85969 | O13: 43229.5
D14: Total current assets | E14: =SUM(E10:E13) -> 10222838 | G14: =SUM(G10:G13) -> 11906287 | I14: =SUM(I10:I13) -> 13014551 | K14: =SUM(K10:K13) -> 9656225 | M14: =SUM(M10:M13) -> 8296389 | O14: =SUM(O10:O13) -> 3042693.5
B15: Deferred tax assets | E15: 970121 | G15: 970120.65 | I15: 133204 | K15: 0 | M15: 200839 | O15: =182813+45953.5 -> 228766.5
B16: Fixed Assets
C17: Corporate Fixed Assets | E17: 3661697.3 | G17: 4049094.3 | I17: 3314316.1 | K17: 2189343 | M17: 1421657 | O17: 896644
C18: Denville | E18: 1490822.1 | G18: 1478736.4 | I18: 1131938.9 | K18: 0 | M18: 0 | O18: 0
C19: Nationals Park | E19: 1178451.4 | G19: 1153121.1 | I19: 0 | K19: 0 | M19: 0 | O19: 0
C20: Spokane Valley | E20: 301213.1 | G20: 0 | I20: 0 | K20: 0 | M20: 0 | O20: 0
C21: Kennewick | E21: 299954.65 | G21: 0 | I21: 0 | K21: 0 | M21: 0 | O21: 0
D22: Total Fixed Assets | E22: =SUM(E17:E21) -> 6932138.5 | G22: =SUM(G17:G21) -> 6680951.8 | I22: =SUM(I17:I21) -> 4446255 | K22: =SUM(K17:K21) -> 2189343 | M22: =SUM(M17:M21) -> 1421657 | O22: =SUM(O17:O21) -> 896644
B24: Accumulated depreciation and amortization | E24: -3099453.2 | G24: -1640788 | I24: -940381 | K24: -538545 | M24: -357861 | O24: -309915
B25: Other assets | E25: 7508461.9 | G25: 7588405.3 | I25: 1745618 | K25: 489935 | M25: 523433 | O25: 376818
D26: Total assets | E26: =E14+E15+E22+E24+E25 -> 22534106 | G26: =G14+G15+G22+G24+G25 -> 25504977 | I26: =I14+I15+I22+I24+I25 -> 18399247 | K26: =K14+K15+K22+K24+K25 -> 11796958 | M26: =M14+M15+M22+M24+M25 -> 10084457 | O26: =O14+O15+O22+O24+O25 -> 4235007
C28: Liabilities and Stockholder's Equity
B29: Current liabilities
C30: Accounts payable | E30: 1376917.4 | G30: 2642356.2 | I30: =1543899 -> 1543899 | K30: 1569455 | M30: 1053321 | O30: 1267134
C31: Goods invoiced not shipped | E31: 4472 | G31: 1028450 | I31: 3003550 | K31: 690867 | M31: 1439563 | O31: 0
C32: Customer deposits | E32: 606027.27 | G32: 411461.18 | I32: 372190 | K32: 1553207 | M32: 2211853 | O32: 0
C33: Deferred revenues (current) | E33: 253662.75 | G33: 522576.68 | I33: 637749 | K33: 566880 | M33: 395359 | O33: 164303.5
C34: Income Tax Payable | E34: 0 | G34: 585269.51 | I34: =1236639+191540 -> 1428179 | K34: =419792+73026 -> 492818 | M34: =294922+55748 -> 350670 | O34: 159823
C35: Notes payable (current) | E35: 0 | G35: 0 | I35: 4146 | K35: 4320 | M35: 754320 | O35: 0
C36: Other current liabilities | E36: 3843484.8 | G36: 3707661.6 | I36: =228829+305946+2774+273156+230377+314924 -> 1356006 | K36: 525147 | M36: 374590 | O36: =539111.5-159823 -> 379288.5
D37: Total current liabilities | E37: =SUM(E30:E36) -> 6084564.2 | G37: =SUM(G30:G36) -> 8897775.2 | I37: =SUM(I30:I36) -> 8345719 | K37: =SUM(K30:K36) -> 5402694 | M37: =SUM(M30:M36) -> 6579676 | O37: =SUM(O30:O36) -> 1970549
B38: Deferred revenues | E38: 1580507.9 | G38: 1705596.4 | I38: 1760043 | K38: 1554562 | M38: 1180375 | O38: 488984
B39: Notes payable | E39: 0 | G39: 0 | I39: 1426 | K39: 15255 | M39: 19714 | O39: 985000
B40: Other liabilities | E40: 5271998.8 | G40: 5839527.8 | I40: 539369 | K40: 5571 | M40: 47588 | O40: 117951.5
D41: Total liabilities | E41: =SUM(E37:E40) -> 12937071 | G41: =SUM(G37:G40) -> 16442899 | I41: =SUM(I37:I40) -> 10646557 | K41: =SUM(K37:K40) -> 6978082 | M41: =SUM(M37:M40) -> 7827353 | O41: =SUM(O37:O40) -> 3562484.5
B42: Stockholder's equity:
C43: Common stock | E43: 3000000 | G43: 3000000 | I43: 3000000 | K43: 3000000 | M43: 3000000 | O43: 3000000
C44: Retained earnings (accumulated deficit) | E44: 6062778.1 | G44: 4752645.3 | I44: 1818782 | K44: =-1476176+733290 -> -742886 | M44: -2327478 | O44: =-2874760+45953.5 -> -2828806.5
C45: Cumulative Translation Adjustment | E45: -373.27 | G45: -700.94 | I45: 45 | K45: 95 | M45: -11 | O45: 0
...

Sheet Income Statement
A2: X GOLF AMERICA, INC.
A3: Consolidated Financial Statements
A4: Statement of Operations (unaudited)
A7: Consolidated Income Statement | D7: Dec. 31, 2025 | F7: Dec. 31, 2024 | H7: Dec. 31, 2023 | J7: Dec. 31, 2022 | L7: Dec. 31, 2021 | N7: Dec. 31, 2020
A8: Revenues:
B9: Equipment and installation | D9: 5505254.7 | F9: 11235231 | H9: 17406298 | J9: 13806632 | L9: 7574521 | N9: 4273426.5
B10: Franchise fees | D10: 489002.41 | F10: 569808.23 | H10: 415296.46 | J10: 331292.12 | L10: 285804 | N10: 90473
B11: Royalties | D11: 6304703 | F11: 4839052.4 | H11: 3746289.3 | J11: 2393325.3 | L11: 1126124 | N11: 484009
B12: Marketing fund revenue | D12: 1000811.8 | F12: 771462.39 | H12: 610059 | J12: 397390.08 | L12: 189372 | N12: 0
B13: Net Store Operations | D13: -959383.54 | F13: -396189.39 | H13: -35232.58 | J13: 0 | L13: 0 | N13: 0
B14: Other revenue | D14: 693171.36 | F14: 523772.72 | H14: 257851.8 | J14: 99095.58 | L14: 789618.4 | N14: 309639.5
C15: Total revenue | D15: =SUM(D9:D14) -> 13033560 | F15: =SUM(F9:F14) -> 17543137 | H15: =SUM(H9:H14) -> 22400562 | J15: =SUM(J9:J14) -> 17027735 | L15: =SUM(L9:L14) -> 9965439.4 | N15: =SUM(N9:N14) -> 5157548
A16: Cost of goods | D16: 4451706.1 | F16: 8179505.8 | H16: 11547572 | J16: =9395180-46703 -> 9348477 | L16: =6352384-733290 -> 5619094 | N16: 2793484.8
C17: Gross profit (loss) | D17: =D15-D16 -> 8581853.6 | F17: =F15-F16 -> 9363631.3 | H17: =H15-H16 -> 10852990 | J17: =J15-J16 -> 7679258.1 | L17: =L15-L16 -> 4346345.4 | N17: =N15-N16 -> 2364063.2
A19: Operating expenses
B20: Advertising & Marketing | D20: 733404.23 | F20: 1326784.7 | H20: 1168243.5 | J20: 578124.2 | L20: 254544.77 | N20: 343208.31
B21: Legal, Professional, Outside Services | D21: 1526419.5 | F21: 1067961.4 | H21: 475154.78 | J21: 285344.24 | L21: 157215.64 | N21: 72485.04
B22: Payroll | D22: 3291765.7 | F22: 3687639.6 | H22: 3383828.5 | J22: 2299524.4 | L22: 1450530.2 | N22: 921677.68
B23: Other Operating Expenses | D23: 1451069.1 | F23: 1361981.1 | H23: 922825.93 | J23: 785521.78 | L23: 608191.37 | N23: 340609.27
C24: Total Operating Expenses | D24: =SUM(D20:D23) -> 7002658.6 | F24: =SUM(F20:F23) -> 7444366.8 | H24: =SUM(H20:H23) -> 5950052.7 | J24: =SUM(J20:J23) -> 3948514.6 | L24: =SUM(L20:L23) -> 2470482 | N24: =SUM(N20:N23) -> 1677980.3
C25: EBITDA | D25: =+D17-D24 -> 1579195 | F25: =+F17-F24 -> 1919264.5 | H25: =+H17-H24 -> 4902937.7 | J25: =+J17-J24 -> 3730743.5 | L25: =+L17-L24 -> 1875863.4 | N25: =+N17-N24 -> 686082.94
A27: Depreciation and amortization | D27: 674966.51 | F27: 846785.08 | H27: 401837 | J27: 180684 | L27: 159961 | N27: 32870.4
A28: Other expenses (income) | D28: 73614.14 | F28: 46915.47 | H28: -278447 | J28: 22994 | L28: =-378+56337-125175-506 -> -69722 | N28: -52995.2
C29: Income (loss) before taxes | D29: =D25-D27-D28 -> 830614.38 | F29: =F25-F27-F28 -> 1025564 | H29: =H25-H27-H28 -> 4779547.7 | J29: =J25-J27-J28 -> 3527065.5 | L29: =L25-L27-L28 -> 1785624.4 | N29: =N25-N27-N28 -> 706207.74
A30: Income tax expense (benefit) | D30: 295984.62 | F30: -284568.88 | H30: 845685 | J30: 465398 | L30: 201031 | N30: 204879
C31: Net income (loss) | D31: =D29-D30 -> 534629.76 | F31: =F29-F30 -> 1310132.8 | H31: =H29-H30 -> 3933862.7 | J31: =J29-J30 -> 3061667.5 | L31: =L29-L30 -> 1584593.4 | N31: =N29-N30 -> 501328.74

Sheet Cash Flows
B2: X GOLF AMERICA, INC.
B3: Consolidated Financial Statements
B4: Statement of Cash Flows (unaudited)
B7: Consolidated Statement of Cash Flows | G7: Dec. 31, 2025 | I7: Dec. 31, 2024 | K7: Dec. 31, 2023 | M7: Dec. 31, 2022 | O7: Dec. 31, 2021 | Q7: Dec. 31, 2020
B8: CASH FLOWS FROM OPERATING ACTIVITES:
C9: Net income (loss) | G9: ='Income Statement'!D31 -> 534629.76 | I9: ='Income Statement'!F31 -> 1310132.8 | K9: ='Income Statement'!H31 -> 3933862.7 | M9: ='Income Statement'!J31 -> 3061667.5 | O9: ='Income Statement'!L31 -> 1584593.4 | Q9: 489006
C10: Adjustments to reconcile Net Income to Net Cash
C11: provided by operations:
C12: Accumulated depreciation and amortization | G12: 1458665 | I12: 700407 | K12: 401836 | M12: 117163 | O12: 47945.4 | Q12: 5884
D13: Accounts receivable | G13: -104209 | I13: 368004 | K13: -1006015 | M13: 714084 | O13: -257312 | Q13: -347697
D14: Inventory | G14: 1847737 | I14: -1040957 | K14: -355608 | M14: -1127737.3 | O14: =-2338156-733290 -> -3071446 | Q14: -383218
D15: Prepaid Expenses and Other Assets | G15: 66678 | I15: -106778 | K15: -339625 | M15: -18940 | O15: -42749 | Q15: 0
D16: Accounts payable | G16: -1265439 | I16: 1098457 | K16: -25555 | M16: 516133 | O16: 416188 | Q16: 712872
D17: Sales Tax payable | G17: -9493 | I17: -80174 | K17: 142897 | M17: 34517 | O17: 8969 | Q17: 43994
D18: Accrued liabilities | G18: -1822515 | I18: -225773 | K18: 1513207 | M18: -1083518 | O18: 3935523 | Q18: -488695
D19: Income tax payable | G19: -281867 | I19: -1679827 | K19: 731355 | M19: 142148 | O19: 139609 | Q19: 34691
D20: Deferred revenues | G20: -125088 | I20: -54446 | K20: 205481 | M20: 374187 | O20: 701391 | Q20: 98303.5
D21: Other cash provided from (used in) operations | G21: 0 | I21: 0 | K21: 0 | M21: 0 | O21: 0 | Q21: 249408.5
B22: Net cash provided by operating activities | G22: =SUM(G9:G21) -> 299098.76 | I22: =SUM(I9:I21) -> 289045.84 | K22: =SUM(K9:K21) -> 5201835.7 | M22: =SUM(M9:M21) -> 2729704.1 | O22: =SUM(O9:O21) -> 3462711.8 | Q22: =SUM(Q9:Q21) -> 414549
B23: INVESTING ACTIVITIES:
C24: Fixed Assets | G24: -251187 | I24: -2234697 | K24: -2256912 | M24: =-767686 -> -767686 | O24: =-689654.5 -> -689654.5 | Q24: =-637300+293 -> -637007
C25: Other cash provided from (used in) investing activities | G25: 0 | I25: 0 | K25: =-1388887+737877+204006+215617+182739+48648 -> 0 | M25: =297859 -> 297859 | O25: 0 | Q25: =-13323-291225-74220.5 -> -378768.5
B26: Net Cash provided by (used in) investing activities | G26: =G24+G25 -> -251187 | I26: =I24+I25 -> -2234697 | K26: =K24+K25 -> -2256912 | M26: =M24+M25 -> -469827 | O26: =O24+O25 -> -689654.5 | Q26: =Q24+Q25 -> -1015775.5
B27: FINANCING ACTIVITIES
C28: Notes payable | G28: -1426 | I28: -4145 | K28: =714346-737877 -> -23531 | M28: -832738 | O28: -296812 | Q28: 0
C29: Dividends Paid | G29: 0 | I29: 0 | K29: -1000000 | M29: -500000 | O29: 0 | Q29: 0
C30: Retained earnings Adjustment | G30: 0 | I30: 0 | K30: 0 | M30: 0 | O30: =3189773-3143820 -> 45953 | Q30: 0
C31: Other cash provided from (used in) financing activities | G31: 0 | I31: 0 | K31: 0 | M31: 0 | O31: 0 | Q31: 296623
B32: Net Cash provided by (used in) financing activities | G32: =SUM(G27:G31) -> -1426 | I32: =SUM(I27:I31) -> -4145 | K32: =SUM(K27:K31) -> -1023531 | M32: =SUM(M27:M31) -> -1332738 | O32: =SUM(O27:O31) -> -250859 | Q32: =SUM(Q27:Q31) -> 296623
B33: NET INCREASE (DECREASE) IN CASH | G33: =+G22+G26+G32 -> 46485.76 | I33: =+I22+I26+I32 -> -1949796.2 | K33: =+K22+K26+K32 -> 1921392.7 | M33: =+M22+M26+M32 -> 927139.15 | O33: =+O22+O26+O32 -> 2522198.3 | Q33: =+Q22+Q26+Q32 -> -304603.5
B34: Cash at beginning of period | G34: =I35 -> 4088509 | I34: =K35 -> 6038305.1 | K34: =M35 -> 4116912.5 | M34: =O35 -> 3189773.3 | O34: 667575 | Q34: 972178.5
B35: Cash at end of period | G35: =+G33+G34 -> 4134994.7 | I35: =+I33+I34 -> 4088509 | K35: =+K33+K34 -> 6038305.1 | M35: =+M33+M34 -> 4116912.5 | O35: =+O33+O34 -> 3189773.3 | Q35: =+Q33+Q34 -> 667575

Sheet Capital Expenses
B2: X GOLF AMERICA, INC.
B3: Consolidated Financial Statements
B4: Capital Expenses
D6: Spend as of | F6: Q1 2024 | G6: Q2 2024 | H6: Q3 2024 | I6: Q4 2024 | J6: 2024 YTD | L6: 2025 YTD | N6: Cumalative to Date | P6: Total Project | Q6: Cumulative Spend
D7: 12/31/2023 | F7: Actual | G7: Actual | H7: Actual | I7: Actual | J7: Actual | L7: Actual | N7: Actual | P7: Budget | Q7: vs. Budget
C8: 2024 Board Approved Projects
C9: Denville Corporate Venue | D9: 1131937 | F9: 282273.2 | G9: 36248.26 | H9: 171689.69 | I9: -143413.6 | J9: =SUM(F9:I9) -> 346797.55 | L9: ='Balance Sheet'!E18-J9-D9 -> 12087.56 | N9: =D9+J9+L9 -> 1490822.1 | P9: 1222000 | Q9: =P9-N9 -> -268822.11
C10: Company Vehicles (1 New Regional Manager) | D10: 0 | G10: 29641.94 | J10: =SUM(F10:I10) -> 29641.94 | L10: -29642 | N10: =D10+J10+L10 -> -0.06 | P10: 35000 | Q10: =P10-N10 -> 35000.06
C11: Simulator Trailer for Activations | D11: 0 | F11: 14420.24 | J11: =SUM(F11:I11) -> 14420.24 | N11: =D11+J11+L11 -> 14420.24 | P11: 25000 | Q11: =P11-N11 -> 10579.76
C12: PCs for new employees | D12: 0 | F12: 5931.27 | G12: 10472.57 | H12: 8174.92 | I12: 3299.18 | J12: =SUM(F12:I12) -> 27877.94 | N12: =D12+J12+L12 -> 27877.94 | P12: 25000 | Q12: =P12-N12 -> -2877.94
C13: Improvements to acquired venues | D13: 0 | J13: =SUM(F13:I13) -> 0 | N13: =D13+J13+L13 -> 0 | P13: 50000 | Q13: =P13-N13 -> 50000
C14: Washington National Corporate Venue | D14: 35263.59 | G14: 232817.61 | H14: 820774.64 | I14: 51659.41 | J14: =SUM(F14:I14) -> 1105251.7 | L14: ='Balance Sheet'!E19-J14-D14 -> 37936.15 | N14: =D14+J14+L14 -> 1178451.4 | P14: 1200000 | Q14: =P14-N14 -> 21548.6
C15: Kennewick and Spokane Valley | D15: 0 | I15: 545747.35 | J15: =SUM(F15:I15) -> 545747.35 | L15: ='Balance Sheet'!E21+'Balance Sheet'!E20-J15 -> 55420.4 | N15: =D15+J15+L15 -> 601167.75 | P15: 0 | Q15: =P15-N15 -> -601167.75
C17: Prior Year Board Approved Projects
C18: Mobile Sim | D18: 160000 | F18: 152247.68 | J18: =SUM(F18:I18) -> 152247.68 | L18: =-71500+92150 -> 20650 | N18: =D18+J18+L18 -> 332897.68 | P18: 275000 | Q18: =P18-N18 -> -57897.68
C19: Club Caddie POS | D19: 79632 | F19: 12712.43 | J19: =SUM(F19:I19) -> 12712.43 | N19: =D19+J19+L19 -> 92344.43 | P19: 125000 | Q19: =P19-N19 -> 32655.57
C20: Total Capital Expenses | D20: =SUM(D8:D19) -> 1406832.6 | F20: =SUM(F9:F19) -> 467584.82 | G20: =SUM(G9:G19) -> 309180.38 | H20: =SUM(H9:H19) -> 1000639.2 | I20: =SUM(I9:I19) -> 457292.34 | J20: =SUM(J9:J19) -> 2234696.8 | K20: =SUM(K9:K19) -> 0 | L20: =SUM(L9:L19) -> 96452.11 | M20: =SUM(M9:M19) -> 0 | N20: =SUM(N9:N19) -> 3737981.5 | P20: =SUM(P9:P19) -> 2957000 | Q20: =SUM(Q9:Q19) -> -780981.49

Sheet Stock Equity
B2: X GOLF AMERICA, INC.
B3: Consolidated Financial Statements
B4: Statements of Changes in Stockholder's Equity (unaudited)
B7: Consolidated Changes in Stockholder's Equity | H7: Retained | J7: Total Stockholder's equity (deficit)
D8: Common Stock | H8: earnings
D9: Shares | F9: Amount | H9: (Accumulated deficit)
B10: Balance at December 31, 2020 | D10: 300000 | F10: 3000000 | H10: ='Balance Sheet'!O44+'Balance Sheet'!O47 -> -2327477.5 | J10: =SUM(F10:H10) -> 672522.5
C11: Dividends Paid | D11: 0 | F11: 0 | H11: ='Balance Sheet'!K42 -> 0 | J11: =+F11+H11 -> 0
C12: Change in Foreign Currency Translation | D12: 0 | F12: 0 | H12: -11 | J12: =+F12+H12 -> -11
C13: Net Income | D13: 0 | F13: 0 | H13: 1584592.5 | J13: =+F13+H13 -> 1584592.5
B14: Balance at December 31, 2021 | D14: =SUM(D10:D13) -> 300000 | F14: =SUM(F10:F13) -> 3000000 | H14: =SUM(H10:H13) -> -742896 | J14: =SUM(J10:J13) -> 2257104
C15: Dividends Paid | D15: 0 | F15: 0 | H15: ='Balance Sheet'!K46 -> -500000 | J15: =+F15+H15 -> -500000
C16: Change in Foreign Currency Translation | D16: 0 | F16: 0 | H16: 105 | J16: =+F16+H16 -> 105
C17: Net Income | D17: 0 | F17: 0 | H17: ='Balance Sheet'!K47 -> 3061667 | J17: =+F17+H17 -> 3061667
B18: Balance at December 31, 2022 | D18: =SUM(D14:D17) -> 300000 | F18: =SUM(F14:F17) -> 3000000 | H18: =SUM(H14:H17) -> 1818876 | J18: =SUM(J14:J17) -> 4818876
C19: Dividends Paid | D19: 0 | F19: 0 | H19: ='Balance Sheet'!I46 -> -1000000 | J19: =+F19+H19 -> -1000000
C20: Change in Foreign Currency Translation | D20: 0 | F20: 0 | H20: -49 | J20: =+F20+H20 -> -49
C21: Net Income | D21: 0 | F21: 0 | H21: ='Balance Sheet'!I47 -> 3933863 | J21: =+F21+H21 -> 3933863
B22: Balance at December 31, 2023 | D22: =SUM(D18:D21) -> 300000 | F22: =SUM(F18:F21) -> 3000000 | H22: =SUM(H18:H21) -> 4752690 | J22: =SUM(J18:J21) -> 7752690
C23: Dividends Paid | D23: 0 | F23: 0 | H23: ='Balance Sheet'!I50 -> 0 | J23: =+F23+H23 -> 0
C24: Change in Foreign Currency Translation | D24: 0 | F24: 0 | H24: -745.66 | J24: =+F24+H24 -> -745.66
C25: Net Income | D25: 0 | F25: 0 | H25: ='Balance Sheet'!G47 -> 1310132.8 | J25: =+F25+H25 -> 1310132.8
B26: Balance at December 31, 2024 | D26: =SUM(D22:D25) -> 300000 | F26: =SUM(F22:F25) -> 3000000 | H26: =SUM(H22:H25) -> 6062077.2 | J26: =SUM(J22:J25) -> 9062077.2
C27: Dividends Paid | D27: 0 | F27: 0 | H27: ='Balance Sheet'!I54 -> 0 | J27: =+F27+H27 -> 0
C28: Change in Foreign Currency Translation | D28: 0 | F28: 0 | H28: 328 | J28: =+F28+H28 -> 328
C29: Net Income | D29: 0 | F29: 0 | H29: ='Balance Sheet'!E47 -> 534630.15 | J29: =+F29+H29 -> 534630.15
B30: Balance at December 31, 2024 | D30: =SUM(D26:D29) -> 300000 | F30: =SUM(F26:F29) -> 3000000 | H30: =SUM(H26:H29) -> 6597035.3 | J30: =SUM(J26:J29) -> 9597035.3
