Workbook

Sheet Sales Data
A1: Location ID | B1: City_State | C1: Region | D1: # of Sims | E1: Royalty % | F1: Sales_Date | G1: Golf | H1: League | I1: Lessons | J1: Beverage | K1: Food | L1: Merchandise | M1: Service Charges | N1: Total Sales | O1: Gift Cards
A2: 2 | B2: Novi, MI | C2: Midwest | D2: 5 | E2: 6 | F2: 42675 | G2: 13667 | H2: 4050 | I2: 714 | J2: 5398 | K2: 1132 | L2: 0 | N2: 24961
A3: 2 | B3: Novi, MI | C3: Midwest | D3: 5 | E3: 6 | F3: 42705 | G3: 38856 | H3: 4440 | I3: 260 | J3: 12289 | K3: 1952 | L3: 80 | N3: 57877
A4: 2 | B4: Novi, MI | C4: Midwest | D4: 5 | E4: 6 | F4: 42736 | G4: 50505.93 | H4: 8355 | I4: 804.98 | J4: 14501.02 | K4: 2530.82 | L4: 0 | N4: 76697.75
A5: 2 | B5: Novi, MI | C5: Midwest | D5: 5 | E5: 6 | F5: 42767 | G5: 49193.06 | H5: 8325.42 | I5: 1145 | J5: 12580.44 | K5: 1494.8 | L5: 103.93 | N5: 72842.65
A6: 2 | B6: Novi, MI | C6: Midwest | D6: 5 | E6: 6 | F6: 42795 | G6: 48383.03 | H6: 0 | I6: 1247.5 | J6: 11795.52 | K6: 2291.34 | L6: 159.1 | N6: 63876.49
A7: 2 | B7: Novi, MI | C7: Midwest | D7: 5 | E7: 6 | F7: 42826 | G7: 15803.6 | H7: 280 | I7: 937.5 | J7: 4459.95 | K7: 973.38 | L7: 1131.97 | N7: 23586.4
A8: 2 | B8: Novi, MI | C8: Midwest | D8: 5 | E8: 6 | F8: 42856 | G8: 6501.01 | H8: 0 | I8: 7375 | J8: 2022.64 | K8: 330.5 | L8: 611.12 | N8: 16840.27
A9: 2 | B9: Novi, MI | C9: Midwest | D9: 5 | E9: 6 | F9: 42887 | G9: 4515.17 | H9: 0 | I9: 2175 | J9: 1124.86 | K9: 178.1 | L9: 1279.96 | N9: 9273.09
A10: 2 | B10: Novi, MI | C10: Midwest | D10: 5 | E10: 6 | F10: 42917 | G10: 2915.29 | H10: 0 | I10: 4300 | J10: 1395.96 | K10: 963.18 | L10: 1763.27 | N10: 11337.7
A11: 2 | B11: Novi, MI | C11: Midwest | D11: 5 | E11: 6 | F11: 42948 | G11: 2932.76 | H11: 0 | I11: 5350 | J11: 1040.75 | K11: 147.74 | L11: 4729.94 | N11: 14201.19
A12: 2 | B12: Novi, MI | C12: Midwest | D12: 5 | E12: 6 | F12: 42979 | G12: 4091.12 | H12: 150 | I12: 640 | J12: 952.23 | K12: 173.72 | L12: 1899.96 | N12: 7907.03
A13: 6 | B13: Grand Rapids, MI | C13: Midwest | D13: 6 | E13: 6 | F13: 42979 | G13: 1000 | H13: 0 | I13: 0 | J13: 152 | K13: 6 | L13: 0 | N13: 1158
... A1305: 35 | B1305: Schaumburg, IL | C1305: Midwest | D1305: 9 | E1305: 6 | F1305: 44774 | G1305: 6657.75 | H1305: 0 | I1305: 1197 | J1305: 1873.67 | K1305: 988.05 | L1305: 0 | N1305: 10716.47
A1306: 61 | B1306: Wrigleyville, IL | C1306: Midwest | D1306: 8 | E1306: VAR | F1306: 44774 | G1306: 15686.25 | H1306: 0 | I1306: 0 | J1306: 10163.76 | K1306: 1727.62 | L1306: 42.5 | N1306: 27620.13
A1307: 68 | B1307: Portland, ME | C1307: Northeast | D1307: 6 | E1307: 7 | F1307: 44774 | G1307: 7315 | H1307: 0 | I1307: 950 | J1307: 4615.75 | K1307: 1043 | L1307: 6904.18 | N1307: 20827.93
A1308: 19 | B1308: Wayland, MA | C1308: Northeast | D1308: 6 | E1308: 6 | F1308: 44774 | G1308: 12656.65 | H1308: 0 | I1308: 4168 | J1308: 2838.65 | K1308: 655.3 | L1308: 83 | N1308: 20401.6
A1309: 11 | B1309: Kalamazoo, MI | C1309: Midwest | D1309: 6 | E1309: 6 | F1309: 44774 | G1309: 8009 | H1309: 1375 | I1309: 1210 | J1309: 3642.65 | K1309: 1056.38 | L1309: 1089.83 | N1309: 16382.86
A1310: 2 | B1310: Novi, MI | C1310: Midwest | D1310: 5 | E1310: 6 | F1310: 44774 | G1310: 10317.5 | H1310: 598 | I1310: 0 | J1310: 3303.5 | K1310: 680.61 | L1310: 86.97 | N1310: 14986.58
A1311: 49 | B1311: Kenosha, WI | C1311: Midwest | D1311: 7 | E1311: 6 | F1311: 44774 | G1311: 3391.01 | H1311: 0 | I1311: 365 | J1311: 2302.77 | K1311: 672.58 | L1311: 264.8 | N1311: 6996.16
A1312: 31 | B1312: Greenwood Village, CO | C1312: Rocky Mountains | D1312: 7 | E1312: 6 | F1312: 44774 | G1312: 18659 | H1312: 2250 | I1312: 100 | J1312: 7683.7 | K1312: 1337.46 | L1312: 521 | N1312: 30551.16
A1313: 9 | B1313: Grand Junction, CO | C1313: Rocky Mountains | D1313: 5 | E1313: 6 | F1313: 44774 | G1313: 9104.5 | H1313: 0 | I1313: 0 | J1313: 4711.35 | K1313: 738.91 | L1313: 0 | N1313: 14554.76
A1314: 15 | B1314: Fort Collins, CO | C1314: Rocky Mountains | D1314: 7 | E1314: 6 | F1314: 44774 | G1314: 16203.5 | H1314: 3987.5 | I1314: 1578.75 | J1314: 7964.8 | K1314: 2287 | L1314: 867.52 | N1314: 32889.07
A1315: 12 | B1315: Rochester Hills, MI | C1315: Midwest | D1315: 6 | E1315: 6 | F1315: 44774 | G1315: 7588.46 | H1315: 0 | I1315: 25 | J1315: 1749.03 | K1315: 423.26 | L1315: 54.98 | N1315: 9840.73
A1316: 76 | B1316: Omaha, NE | C1316: Midwest | D1316: 7 | E1316: 6 | F1316: 44774 | G1316: 9481.3 | H1316: 0 | I1316: 0 | J1316: 3995.18 | K1316: 692.5 | L1316: 0 | N1316: 14168.98
A1317: 7 | B1317: Ann Arbor, MI | C1317: Midwest | D1317: 6 | E1317: 6 | F1317: 44774 | G1317: 3787.5 | H1317: 0 | I1317: 0 | J1317: 863.75 | K1317: 298 | L1317: 59.99 | N1317: 5009.24
A1318: 14 | B1318: Woodbury, MN | C1318: Midwest | D1318: 6 | E1318: 4.5 | F1318: 44774 | G1318: 8040 | H1318: 1920 | I1318: 0 | J1318: 4148 | K1318: 1485 | L1318: 20 | N1318: 15613
... A1366: 35 | B1366: Schaumburg, IL | C1366: Midwest | D1366: 9 | E1366: 6 | F1366: 44805 | G1366: 7508 | H1366: 0 | I1366: 722.5 | J1366: 4609.45 | K1366: 1088.92 | L1366: 18.08 | N1366: 13946.95
A1367: 61 | B1367: Wrigleyville, IL | C1367: Midwest | D1367: 8 | E1367: VAR | F1367: 44805 | G1367: 24688.5 | H1367: 1875 | I1367: 0 | J1367: 17740.29 | K1367: 3341 | L1367: 0 | N1367: 47644.79
A1368: 68 | B1368: Portland, ME | C1368: Northeast | D1368: 6 | E1368: 7 | F1368: 44805 | G1368: 9387.5 | H1368: 0 | I1368: 385 | J1368: 3807.25 | K1368: 738 | L1368: 6098.87 | N1368: 20416.62
A1369: 11 | B1369: Kalamazoo, MI | C1369: Midwest | D1369: 6 | E1369: 6 | F1369: 44805 | G1369: 5472.97 | H1369: 20797.5 | I1369: 800 | J1369: 3470.5 | K1369: 735.85 | L1369: 52 | N1369: 31328.82
A1370: 49 | B1370: Kenosha, WI | C1370: Midwest | D1370: 7 | E1370: 6 | F1370: 44805 | G1370: 3506 | H1370: 1200 | I1370: 210 | J1370: 2753.47 | K1370: 709.15 | L1370: 227.26 | N1370: 8605.88
A1371: 9 | B1371: Grand Junction, CO | C1371: Rocky Mountains | D1371: 5 | E1371: 6 | F1371: 44805 | G1371: 10747.87 | H1371: 2600 | I1371: 0 | J1371: 5302.5 | K1371: 662 | L1371: 15.99 | N1371: 19328.36
A1372: 31 | B1372: Greenwood Village, CO | C1372: Rocky Mountains | D1372: 7 | E1372: 6 | F1372: 44805 | G1372: 18400.5 | H1372: 16200 | I1372: 399 | J1372: 10541.5 | K1372: 2157.12 | L1372: 35.1 | N1372: 47733.22
A1373: 15 | B1373: Fort Collins, CO | C1373: Rocky Mountains | D1373: 7 | E1373: 6 | F1373: 44805 | G1373: 19181.24 | H1373: 21312.5 | I1373: 6439.25 | J1373: 8920.96 | K1373: 1791.96 | L1373: 851.33 | N1373: 58497.24
A1374: 76 | B1374: Omaha, NE | C1374: Midwest | D1374: 7 | E1374: 6 | F1374: 44805 | G1374: 8260 | H1374: 3162.5 | I1374: 0 | J1374: 4952.32 | K1374: 755.68 | L1374: 87.56 | N1374: 17218.06
A1375: 13 | B1375: Lansing, MI | C1375: Midwest | D1375: 6 | E1375: 6 | F1375: 44805 | G1375: 6068.64 | H1375: 3300 | I1375: 0 | J1375: 985.74 | K1375: 312.43 | L1375: 0 | N1375: 10666.81
A1376: 47 | B1376: Commack, NY | C1376: Mid Atlantic | D1376: 9 | E1376: 6 | F1376: 44805 | G1376: 17538 | H1376: 2500 | I1376: 3855 | J1376: 5074.17 | K1376: 1894.87 | L1376: 400.96 | N1376: 31263
A1377: 19 | B1377: Wayland, MA | C1377: Northeast | D1377: 6 | E1377: 6 | F1377: 44805 | G1377: 16449.64 | H1377: 14306 | I1377: 2620 | J1377: 4746.66 | K1377: 940.7 | L1377: 210.98 | N1377: 39273.98
A1378: 4 | B1378: Huntsville, AL | C1378: South | D1378: 5 | E1378: 6 | F1378: 44805 | G1378: 16319.08 | H1378: 0 | I1378: 500 | J1378: 8283.2 | K1378: 4344.62 | L1378: 197 | N1378: 29643.9
...

Sheet Total Sales by Month
A1: Total Sales by Location by Date
A2: *This document is strictly confidential and may not be shared or redistributed in any form without written consent from the corporate office.
A4: Sum of Total Sales | F4: Years | G4: Sales_Date
F5: 2023 | G5: 2024 | H5: 2025 | I5: 2026 | N5: 2026 Total
A6: Location ID | B6: City_State | C6: Region | D6: # of Sims | E6: Royalty % | I6: Jan | J6: Feb | K6: Mar | L6: Apr | M6: May
A7: 2 | B7: Novi, MI | C7: Midwest | D7: 5 | E7: 6 | F7: 649140.12 | G7: 622105.56 | H7: 615190.81 | I7: 135182.95 | J7: 78656.61 | K7: 71484.68 | L7: 39761.48 | M7: 20831.05 | N7: 345916.77
A8: 4 | B8: Huntsville, AL | C8: South | D8: 5 | E8: 6 | F8: 552143.26 | G8: 534697.4 | H8: 556953.33 | I8: 65699.18 | J8: 39950.35 | K8: 27450.74 | L8: 19377.04 | M8: 28046.01 | N8: 180523.32
A9: 6 | B9: Grand Rapids, MI | C9: Midwest | D9: 6 | E9: 6 | F9: 912130.77 | G9: 707186.72 | H9: 632528.89 | I9: 106215.06 | J9: 127057.04 | K9: 87232.51 | L9: 52372.34 | M9: 11918.66 | N9: 384795.61
A10: 7 | B10: Ann Arbor, MI | C10: Midwest | D10: 6 | E10: 6 | F10: 458482.74 | G10: 376475.25 | H10: 508990.01 | I10: 139544.23 | J10: 90580.45 | K10: 76427.84 | L10: 33318.37 | M10: 17898.97 | N10: 357769.86
A11: 8 | B11: Shelby Twp, MI | C11: Midwest | D11: 6 | E11: 6 | F11: 813062.42 | G11: 723540.51 | H11: 803888.63 | I11: 161515.39 | J11: 115081.59 | K11: 117676.66 | L11: 64800.3 | M11: 24155.52 | N11: 483229.46
A12: 9 | B12: Grand Junction, CO | C12: Rocky Mountains | D12: 5 | E12: 6 | F12: 393696.76 | G12: 484489.45 | H12: 579043.65 | I12: 117146.85 | J12: 66991.09 | K12: 42749.3 | L12: 39430.5 | M12: 34175.9 | N12: 300493.64
A13: 10 | B13: Holland, MI | C13: Midwest | D13: 6 | E13: 6 | F13: 731678.9 | G13: 646981.99 | H13: 691066.44 | I13: 122747.93 | J13: 131775.65 | K13: 100373.79 | L13: 55036.3 | M13: 13042.23 | N13: 422975.9
A14: 11 | B14: Kalamazoo, MI | C14: Midwest | D14: 6 | E14: 6 | F14: 727827.25 | G14: 672687.92 | H14: 763572.52 | I14: 159387.02 | J14: 140882.27 | K14: 122053.96 | L14: 59194.33 | M14: 14339.68 | N14: 495857.26
A15: 12 | B15: Rochester Hills, MI | C15: Midwest | D15: 6 | E15: 6 | F15: 689477.23 | G15: 584674.29 | H15: 564363.58 | I15: 138190.15 | J15: 79041.37 | K15: 73576.86 | L15: 33079.86 | M15: 10015.63 | N15: 333903.87
A16: 13 | B16: Lansing, MI | C16: Midwest | D16: 6 | E16: 6 | F16: 806910.02 | G16: 765165.57 | H16: 791750.72 | I16: 121710.34 | J16: 109160.81 | K16: 95766.62 | L16: 54329.13 | M16: 23738.56 | N16: 404705.46
A17: 14 | B17: Woodbury, MN | C17: Midwest | D17: 6 | E17: 4.5 | F17: 661148.09 | G17: 543123.17 | H17: 618247.15 | I17: 102293.66 | J17: 76900.79 | K17: 75371.55 | L17: 42476.34 | M17: 7268.01 | N17: 304310.35
A18: 15 | B18: Fort Collins, CO | C18: Rocky Mountains | D18: 7 | E18: 6 | F18: 1205504.8 | G18: 1054459.3 | H18: 1102766.4 | I18: 130332.39 | J18: 102785.14 | K18: 94532.68 | L18: 59351.07 | M18: 61360.95 | N18: 448362.23
... A25: 22 | B25: Champlin, MN | C25: Midwest | D25: 6 | E25: 4.5 | F25: 660460.36 | G25: 533955.13 | H25: 576536.1 | I25: 106896.67 | J25: 78359.03 | K25: 82310.02 | L25: 42805.02 | M25: 12682.49 | N25: 323053.23
A26: 23 | B26: Wexford, PA | C26: Mid Atlantic | F26: 644310.93 | G26: 671547.34 | H26: 420805.73
A27: 24 | B27: Garnet Valley, PA | C27: Mid Atlantic | F27: 776757.97 | G27: 766644.86 | H27: 807148.29 | I27: 151090.12 | J27: 137352.01 | K27: 81814.92 | L27: 34805.2 | M27: 40239.91 | N27: 445302.16
A28: 25 | B28: Richmond, VA | C28: South | D28: 6 | E28: 6 | F28: 676847.56 | G28: 645884.02 | H28: 709339.03 | I28: 102457.11 | J28: 82543.78 | K28: 49870.74 | L28: 23726.67 | M28: 40384.08 | N28: 298982.38
A29: 26 | B29: Glenview, IL | C29: Midwest | D29: 8 | E29: 6 | F29: 848776.45 | G29: 711892.65 | H29: 663027.37 | I29: 121718.1 | J29: 103245.1 | K29: 86455.53 | L29: 47201.61 | M29: 20392.29 | N29: 379012.63
A30: 27 | B30: Royal Oak, MI | C30: Midwest | D30: 6 | E30: 6 | F30: 936404.71 | G30: 846491.99 | H30: 845979.91 | I30: 110781.66 | J30: 152709.37 | K30: 106986.19 | L30: 57539.5 | M30: 25609.38 | N30: 453626.1
A31: 28 | B31: Madison, WI | C31: Midwest | D31: 8 | E31: 6 | F31: 654733.05 | G31: 503363.96 | H31: 496268.48 | I31: 115128.9 | J31: 94599.2 | K31: 77981.48 | L31: 43693.98 | M31: 11982.26 | N31: 343385.82
A32: 29 | B32: Middleton, WI | C32: Midwest | D32: 7 | E32: 6 | F32: 609074.5 | G32: 530080.78 | H32: 597572.44 | I32: 107749.55 | J32: 88086.37 | K32: 73510.86 | L32: 41134.95 | M32: 15386.4 | N32: 325868.13
A33: 30 | B33: Mequon, WI | C33: Midwest | D33: 7 | E33: 6 | F33: 642614.93 | G33: 583072.46 | H33: 624828.31 | I33: 98964.19 | J33: 127313.64 | K33: 77990.64 | L33: 70940.12 | M33: 29462.84 | N33: 404671.43
A34: 31 | B34: Greenwood Village, CO | C34: Rocky Mountains | D34: 7 | E34: 6 | F34: 1279896.9 | G34: 1225561.5 | H34: 1061116.6 | I34: 136174.64 | J34: 95039.19 | K34: 83426.63 | L34: 66090.33 | M34: 69303.04 | N34: 450033.83
A35: 32 | B35: Canton, MI | C35: Midwest | D35: 7 | E35: 7 | F35: 810150.57 | G35: 736553.43 | H35: 792402.77 | I35: 169043.64 | J35: 123562.68 | K35: 115159.44 | L35: 49689.96 | M35: 22378.89 | N35: 479834.61
A36: 33 | B36: Lincoln, RI | C36: Northeast | D36: 6 | E36: 6 | F36: 867756.39 | G36: 687299.41 | H36: 750551.87 | I36: 152700.6 | J36: 124084.91 | K36: 123474.56 | L36: 39452.81 | M36: 27655.91 | N36: 467368.79
A37: 34 | B37: Woodhaven, MI | C37: Midwest | D37: 7 | E37: 6 | F37: 840742.69 | G37: 808203.74 | H37: 941365.17 | I37: 210506.28 | J37: 134444.25 | K37: 125871.27 | L37: 72696.8 | M37: 38130.62 | N37: 581649.22
A38: 35 | B38: Schaumburg, IL | C38: Midwest | D38: 9 | E38: 6 | F38: 767090.64 | G38: 749129.25 | H38: 917942.66 | I38: 172196.53 | J38: 144008.04 | K38: 101347.33 | L38: 63078.08 | M38: 25462.24 | N38: 506092.22
A39: 36 | B39: Leawood, KS | C39: Midwest | D39: 7 | E39: 6 | F39: 803505.77 | G39: 825834.09 | H39: 983769.19 | I39: 153549.67 | J39: 107838.81 | K39: 81700.49 | L39: 54639.25 | M39: 39912.73 | N39: 437640.95
A40: 37 | B40: Easton, PA | C40: Mid Atlantic | F40: 513065.83 | G40: 619333.75 | H40: 703556.15 | I40: 146257.77 | J40: 126804.45 | K40: 88067.31 | L40: 28786.5 | M40: 28523.49 | N40: 418439.52
A41: 38 | B41: Downers Grove, IL | C41: Midwest | D41: 8 | E41: 6 | F41: 620760.16 | G41: 548238.53 | H41: 650529.01 | I41: 112205.42 | J41: 141183.76 | K41: 72376.95 | L41: 36280.37 | M41: 8464.83 | N41: 370511.33
A42: 39 | B42: Hilton Head, SC | C42: South | D42: 6 | E42: 6 | F42: 734997.03 | G42: 480653.92
A43: 40 | B43: Burlington, MA | C43: Northeast | D43: 7 | E43: 6 | F43: 1311718.3 | G43: 1292097.8 | H43: 1355665 | I43: 182102.58 | J43: 180958.42 | K43: 175090.51 | L43: 63694.95 | M43: 59893.26 | N43: 661739.72
A44: 41 | B44: South Charlotte, SC | C44: South | D44: 5 | E44: 6 | F44: 602936.12 | G44: 648502.31 | H44: 623265.63 | I44: 63894.39 | J44: 52478.01 | K44: 30420.38 | L44: 23742.71 | M44: 48374.26 | N44: 218909.75
A45: 42 | B45: Orland Park, IL | C45: Midwest | D45: 8 | E45: 6 | F45: 734866.4 | G45: 595840.92 | H45: 592897.34 | I45: 130827.34 | J45: 120959.38 | K45: 97318.61 | L45: 63585.3 | M45: 22490.4 | N45: 435181.03
A46: 43 | B46: Kildeer, IL | C46: Midwest | D46: 10 | E46: 6 | F46: 759278.55 | G46: 679566.66 | H46: 770923.3 | I46: 150945.42 | J46: 122030.02 | K46: 96763.41 | L46: 60608.26 | M46: 24159.45 | N46: 454506.56
A47: 44 | B47: Columbus, OH | C47: Midwest | D47: 7 | E47: 6 | F47: 1062440 | G47: 925791.68 | H47: 1070740.7 | I47: 151005.76 | J47: 135123.85 | K47: 109393.23 | L47: 53914.96 | M47: 59569.22 | N47: 509007.02
...

Sheet Category Sales
A1: Category Sales by Location for Month
A2: *This document is strictly confidential and may not be shared or redistributed in any form without written consent from the corporate office.
A4: Years | B4: 2026
A5: Sales_Date | B5: May
E7: Categories
A8: Location ID | B8: City_State | C8: Region | D8: # of Sims | E8: Golf | F8: League | G8: Lessons | H8: Beverage | I8: Food | J8: Merchandise | K8: Service Charge | L8: Total Sales
A9: 2 | B9: Novi, MI | C9: Midwest | D9: 5 | E9: 15094.85 | F9: 1080 | G9: 0 | H9: 3470.48 | I9: 994.72 | J9: 191 | K9: 0 | L9: 20831.05
A10: 4 | B10: Huntsville, AL | C10: South | D10: 5 | E10: 18847.77 | F10: 1735 | G10: 0 | H10: 5752.8 | I10: 1710.44 | J10: 0 | K10: 0 | L10: 28046.01
A11: 6 | B11: Grand Rapids, MI | C11: Midwest | D11: 6 | E11: 7851.65 | F11: 45 | G11: 1240 | H11: 2265 | I11: 512.02 | J11: 4.99 | K11: 0 | L11: 11918.66
A12: 7 | B12: Ann Arbor, MI | C12: Midwest | D12: 6 | E12: 12919.96 | F12: 0 | G12: 0 | H12: 2943.5 | I12: 905 | J12: 1130.51 | K12: 0 | L12: 17898.97
A13: 8 | B13: Shelby Twp, MI | C13: Midwest | D13: 6 | E13: 12339.97 | F13: 1490 | G13: 577.5 | H13: 8447.12 | I13: 1253.96 | J13: 46.97 | K13: 0 | L13: 24155.52
A14: 9 | B14: Grand Junction, CO | C14: Rocky Mountains | D14: 5 | E14: 19783.29 | F14: 4600 | G14: 0 | H14: 8438.21 | I14: 1327.1 | J14: 27.3 | K14: 0 | L14: 34175.9
A15: 10 | B15: Holland, MI | C15: Midwest | D15: 6 | E15: 8838.99 | F15: 0 | G15: 475 | H15: 2860.25 | I15: 843 | J15: 24.99 | K15: 0 | L15: 13042.23
A16: 11 | B16: Kalamazoo, MI | C16: Midwest | D16: 6 | E16: 7180.08 | F16: 560 | G16: 1230 | H16: 4168.68 | I16: 728 | J16: 472.92 | K16: 0 | L16: 14339.68
A17: 12 | B17: Rochester Hills, MI | C17: Midwest | D17: 6 | E17: 7689.45 | F17: 180 | G17: 0 | H17: 1740.06 | I17: 379.62 | J17: 26.5 | K17: 0 | L17: 10015.63
A18: 13 | B18: Lansing, MI | C18: Midwest | D18: 6 | E18: 17547.96 | F18: 0 | G18: 125 | H18: 4654.8 | I18: 1410.8 | J18: 0 | K18: 0 | L18: 23738.56
A19: 14 | B19: Woodbury, MN | C19: Midwest | D19: 6 | E19: 2660.01 | F19: 125 | G19: 447.5 | H19: 3333.5 | I19: 702 | J19: 0 | K19: 0 | L19: 7268.01
A20: 15 | B20: Fort Collins, CO | C20: Rocky Mountains | D20: 7 | E20: 34440.5 | F20: 7600 | G20: 1290 | H20: 14237.65 | I20: 2033.2 | J20: 1759.6 | K20: 0 | L20: 61360.95
... A143: 902 | B143: Washington, DC | C143: Mid Atlantic | D143: 8 | E143: 16724.8 | F143: 1786 | G143: 0 | H143: 5775.95 | I143: 1390.13 | J143: 0 | K143: 0 | L143: 25676.88
A144: Grand Total | E144: 3126634.6 | F144: 150710.6 | G144: 84700.19 | H144: 1214166.1 | I144: 413612.85 | J144: 53868.49 | K144: 22743.42 | L144: 5066436.2

Sheet Lesson Sales by Month
A1: Lesson Sales by Location for Month
A2: *This document is strictly confidential and may not be shared or redistributed in any form without written consent from the corporate office.
A4: Lessons | D4: Years | E4: Sales_Date
D5: 2023 | E5: 2024 | F5: 2025 | G5: 2026 | L5: 2026 Total
A6: Location ID | B6: City_State | C6: Region | G6: Jan | H6: Feb | I6: Mar | J6: Apr | K6: May
A7: 2 | B7: Novi, MI | C7: Midwest | D7: -468.5 | E7: 0 | F7: 0 | G7: 0 | H7: 0 | I7: 0 | J7: 0 | K7: 0 | L7: 0
A8: 4 | B8: Huntsville, AL | C8: South | D8: 18310.82 | E8: 7940 | F8: 1919.64 | G8: 0 | H8: 0 | I8: 0 | J8: 0 | K8: 0 | L8: 0
A9: 6 | B9: Grand Rapids, MI | C9: Midwest | D9: 26212.8 | E9: 18619.06 | F9: 10565.5 | G9: 1414 | H9: 170 | I9: 530 | J9: 455 | K9: 1240 | L9: 3809
A10: 7 | B10: Ann Arbor, MI | C10: Midwest | D10: 0 | E10: 0 | F10: 250 | G10: 0 | H10: 0 | I10: 0 | J10: 0 | K10: 0 | L10: 0
A11: 8 | B11: Shelby Twp, MI | C11: Midwest | D11: 5457 | E11: 925 | F11: 6365 | G11: 435 | H11: 1030 | I11: 555 | J11: 1290 | K11: 577.5 | L11: 3887.5
A12: 9 | B12: Grand Junction, CO | C12: Rocky Mountains | D12: 0 | E12: 0 | F12: 0 | G12: 0 | H12: 0 | I12: 0 | J12: 0 | K12: 0 | L12: 0
A13: 10 | B13: Holland, MI | C13: Midwest | D13: 8317.09 | E13: 6978 | F13: 13778.24 | G13: 285 | H13: 260 | I13: 1760 | J13: 1220 | K13: 475 | L13: 4000
A14: 11 | B14: Kalamazoo, MI | C14: Midwest | D14: 17210 | E14: 19414.99 | F14: 20064.06 | G14: 3314 | H14: 2300 | I14: 3530 | J14: 1875 | K14: 1230 | L14: 12249
A15: 12 | B15: Rochester Hills, MI | C15: Midwest | D15: 7721.21 | E15: 3330 | F15: 645 | G15: 0 | H15: 0 | I15: 0 | J15: 0 | K15: 0 | L15: 0
A16: 13 | B16: Lansing, MI | C16: Midwest | D16: 12370 | E16: 12835 | F16: 23235 | G16: 2515 | H16: 650 | I16: 3395 | J16: 1100 | K16: 125 | L16: 7785
A17: 14 | B17: Woodbury, MN | C17: Midwest | D17: 4190 | E17: 2570 | F17: 12033.65 | G17: 3787.08 | H17: 1711.25 | I17: 671.25 | J17: 1266.25 | K17: 447.5 | L17: 7883.33
A18: 15 | B18: Fort Collins, CO | C18: Rocky Mountains | D18: 59508.43 | E18: 37936.95 | F18: 20485 | G18: 2515 | H18: 2284 | I18: 1050 | J18: 775 | K18: 1290 | L18: 7914
... A25: 22 | B25: Champlin, MN | C25: Midwest | D25: 6580 | E25: 9585 | F25: 6666 | G25: 893 | H25: 1173 | I25: 537.5 | J25: 447.5 | K25: 268.75 | L25: 3319.75
A26: 23 | B26: Wexford, PA | C26: Mid Atlantic | D26: 18525 | E26: 18095 | F26: 9415
A27: 24 | B27: Garnet Valley, PA | C27: Mid Atlantic | D27: 18521.88 | E27: 23450 | F27: 14060 | G27: 1082 | H27: 2800 | I27: 4514 | J27: 3660 | K27: 670 | L27: 12726
A28: 25 | B28: Richmond, VA | C28: South | D28: 6051.53 | E28: 821.71 | F28: 328 | G28: 0 | H28: 48 | I28: 0 | J28: 0 | K28: 0 | L28: 48
A29: 26 | B29: Glenview, IL | C29: Midwest | D29: 1890 | E29: 3410 | F29: 3495 | G29: 0 | H29: 0 | I29: 0 | J29: 0 | K29: 0 | L29: 0
A30: 27 | B30: Royal Oak, MI | C30: Midwest | D30: 3015 | E30: 4134 | F30: 4835 | G30: 0 | H30: 165 | I30: 145 | J30: 325 | K30: 325 | L30: 960
A31: 28 | B31: Madison, WI | C31: Midwest | D31: 6719.11 | E31: 2336.43 | F31: 1788 | G31: 0 | H31: 0 | I31: 0 | J31: 0 | K31: 0 | L31: 0
A32: 29 | B32: Middleton, WI | C32: Midwest | D32: 6606.68 | E32: 2380 | F32: 1140 | G32: 0 | H32: 0 | I32: 0 | J32: 0 | K32: 0 | L32: 0
A33: 30 | B33: Mequon, WI | C33: Midwest | D33: 8735 | E33: 10715.87 | F33: 13260.56 | G33: 1880 | H33: 1975 | I33: 893 | J33: 1062 | K33: 2179 | L33: 7989
A34: 31 | B34: Greenwood Village, CO | C34: Rocky Mountains | D34: 22381 | E34: 24412.2 | F34: 1850 | G34: 0 | H34: 0 | I34: 0 | J34: 0 | K34: 0 | L34: 0
A35: 32 | B35: Canton, MI | C35: Midwest | D35: 6550 | E35: 3630 | F35: 95 | G35: 0 | H35: 0 | I35: 0 | J35: 0 | K35: 0 | L35: 0
A36: 33 | B36: Lincoln, RI | C36: Northeast | D36: 0 | E36: 0 | F36: 2430 | G36: 360 | H36: 180 | I36: 270 | J36: 180 | K36: 0 | L36: 990
A37: 34 | B37: Woodhaven, MI | C37: Midwest | D37: 22530 | E37: 31275 | F37: 8790 | G37: 0 | H37: 0 | I37: 0 | J37: 0 | K37: 0 | L37: 0
A38: 35 | B38: Schaumburg, IL | C38: Midwest | D38: 14600 | E38: 50 | F38: 0 | G38: 0 | H38: 0 | I38: 0 | J38: 0 | K38: 0 | L38: 0
... A41: 38 | B41: Downers Grove, IL | C41: Midwest | D41: 3773 | E41: 1930 | F41: 10300 | G41: 915 | H41: 1050 | I41: 945 | J41: 0 | K41: 0 | L41: 2910
A42: 39 | B42: Hilton Head, SC | C42: South | D42: 1150 | E42: 0
A43: 40 | B43: Burlington, MA | C43: Northeast | D43: 9010 | E43: 13265 | F43: 5415 | G43: 165 | H43: 125 | I43: 500 | J43: 125 | K43: 0 | L43: 915
A44: 41 | B44: South Charlotte, SC | C44: South | D44: 8837.41 | E44: 12553.7 | F44: 17405.76 | G44: 1729.98 | H44: 1724.98 | I44: 795 | J44: 1439.99 | K44: 1625 | L44: 7314.95
A45: 42 | B45: Orland Park, IL | C45: Midwest | D45: 8514.82 | E45: 0 | F45: 0 | G45: 0 | H45: 0 | I45: 0 | J45: 0 | K45: 0 | L45: 0
A46: 43 | B46: Kildeer, IL | C46: Midwest | D46: 3721 | E46: 24692 | F46: 6531 | G46: 0 | H46: 0 | I46: 0 | J46: 0 | K46: 0 | L46: 0
A47: 44 | B47: Columbus, OH | C47: Midwest | D47: 4120 | E47: 15150 | F47: 9375 | G47: 0 | H47: 0 | I47: 0 | J47: 0 | K47: 0 | L47: 0
A48: 45 | B48: Powell, OH | C48: Midwest | E48: 3650 | F48: 3050 | G48: 0 | H48: 0 | I48: 0 | J48: 0 | K48: 0 | L48: 0
A49: 47 | B49: Commack, NY | C49: Mid Atlantic | D49: 21737.03 | E49: 102857 | F49: 118353.07 | G49: 10984.5 | H49: 11769.22 | I49: 11316.14 | J49: 7872.96 | K49: 9596.49 | L49: 51539.31
...

Sheet Category Avg by # Sims
A1: Category Avg by # Sims
A2: *This document is strictly confidential and may not be shared or redistributed in any form without written consent from the corporate office.
A4: Years | B4: 2026
A5: Sales_Date | B5: May
E7: Average Per Sim
A8: Location ID | B8: City_State | C8: Region | D8: # of Sims | E8: Golf | F8: League | G8: Lessons | H8: Beverage | I8: Food | J8: Merchandise | K8: Total Sales
A9: 2 | B9: Novi, MI | C9: Midwest | D9: 5 | E9: 3018.97 | F9: 216 | G9: 0 | H9: 694.096 | I9: 198.944 | J9: 38.2 | K9: 4166.21
A10: 4 | B10: Huntsville, AL | C10: South | D10: 5 | E10: 3769.554 | F10: 347 | G10: 0 | H10: 1150.56 | I10: 342.088 | J10: 0 | K10: 5609.202
A11: 6 | B11: Grand Rapids, MI | C11: Midwest | D11: 6 | E11: 1308.6083 | F11: 7.5 | G11: 206.66667 | H11: 377.5 | I11: 85.336667 | J11: 0.83166667 | K11: 1986.4433
A12: 7 | B12: Ann Arbor, MI | C12: Midwest | D12: 6 | E12: 2153.3267 | F12: 0 | G12: 0 | H12: 490.58333 | I12: 150.83333 | J12: 188.41833 | K12: 2983.1617
A13: 8 | B13: Shelby Twp, MI | C13: Midwest | D13: 6 | E13: 2056.6617 | F13: 248.33333 | G13: 96.25 | H13: 1407.8533 | I13: 208.99333 | J13: 7.8283333 | K13: 4025.92
A14: 9 | B14: Grand Junction, CO | C14: Rocky Mountains | D14: 5 | E14: 3956.658 | F14: 920 | G14: 0 | H14: 1687.642 | I14: 265.42 | J14: 5.46 | K14: 6835.18
A15: 10 | B15: Holland, MI | C15: Midwest | D15: 6 | E15: 1473.165 | F15: 0 | G15: 79.166667 | H15: 476.70833 | I15: 140.5 | J15: 4.165 | K15: 2173.705
A16: 11 | B16: Kalamazoo, MI | C16: Midwest | D16: 6 | E16: 1196.68 | F16: 93.333333 | G16: 205 | H16: 694.78 | I16: 121.33333 | J16: 78.82 | K16: 2389.9467
A17: 12 | B17: Rochester Hills, MI | C17: Midwest | D17: 6 | E17: 1281.575 | F17: 30 | G17: 0 | H17: 290.01 | I17: 63.27 | J17: 4.4166667 | K17: 1669.2717
A18: 13 | B18: Lansing, MI | C18: Midwest | D18: 6 | E18: 2924.66 | F18: 0 | G18: 20.833333 | H18: 775.8 | I18: 235.13333 | J18: 0 | K18: 3956.4267
A19: 14 | B19: Woodbury, MN | C19: Midwest | D19: 6 | E19: 443.335 | F19: 20.833333 | G19: 74.583333 | H19: 555.58333 | I19: 117 | J19: 0 | K19: 1211.335
A20: 15 | B20: Fort Collins, CO | C20: Rocky Mountains | D20: 7 | E20: 4920.0714 | F20: 1085.7143 | G20: 184.28571 | H20: 2033.95 | I20: 290.45714 | J20: 251.37143 | K20: 8765.85
... A143: 902 | B143: Washington, DC | C143: Mid Atlantic | D143: 8 | E143: 2090.6 | F143: 223.25 | G143: 0 | H143: 721.99375 | I143: 173.76625 | J143: 0 | K143: 3209.61
A144: Grand Total | E144: 3171.029 | F144: 152.85051 | G144: 85.90283 | H144: 1231.4057 | I144: 419.48565 | J144: 54.633357 | K144: 5138.3734

Sheet Attachments (as % of Golf)
A1: Attachment Rate (as % of Golf Revenue)
A2: *This document is strictly confidential and may not be shared or redistributed in any form without written consent from the corporate office.
A4: Years | B4: 2026
A5: Sales_Date | B5: May
E7: Attachment Rate
A8: Location ID | B8: City_State | C8: Region | D8: # of Sims | E8: Total Golf Revenue | F8: League | G8: Lessons | H8: Beverage | I8: Food | J8: Merchandise
A9: 2 | B9: Novi, MI | C9: Midwest | D9: 5 | E9: 15094.85 | F9: 0.071547581 | G9: 0 | H9: 0.22991153 | I9: 0.065897972 | J9: 0.012653322
A10: 4 | B10: Huntsville, AL | C10: South | D10: 5 | E10: 18847.77 | F10: 0.09205333 | G10: 0 | H10: 0.30522444 | I10: 0.090750259 | J10: 0
A11: 6 | B11: Grand Rapids, MI | C11: Midwest | D11: 6 | E11: 7851.65 | F11: 0.0057312794 | G11: 0.15792859 | H11: 0.2884744 | I11: 0.065211771 | J11: 0.00063553521
A12: 7 | B12: Ann Arbor, MI | C12: Midwest | D12: 6 | E12: 12919.96 | F12: 0 | G12: 0 | H12: 0.22782578 | I12: 0.070046656 | J12: 0.087501045
A13: 8 | B13: Shelby Twp, MI | C13: Midwest | D13: 6 | E13: 12339.97 | F13: 0.12074584 | G13: 0.046799141 | H13: 0.68453327 | I13: 0.10161775 | J13: 0.0038063302
A14: 9 | B14: Grand Junction, CO | C14: Rocky Mountains | D14: 5 | E14: 19783.29 | F14: 0.23251946 | G14: 0 | H14: 0.42653219 | I14: 0.067081866 | J14: 0.0013799525
A15: 10 | B15: Holland, MI | C15: Midwest | D15: 6 | E15: 8838.99 | F15: 0 | G15: 0.053739172 | H15: 0.32359466 | I15: 0.095372888 | J15: 0.0028272461
A16: 11 | B16: Kalamazoo, MI | C16: Midwest | D16: 6 | E16: 7180.08 | F16: 0.07799356 | G16: 0.17130728 | H16: 0.58058963 | I16: 0.10139163 | J16: 0.065865561
A17: 12 | B17: Rochester Hills, MI | C17: Midwest | D17: 6 | E17: 7689.45 | F17: 0.023408696 | G17: 0 | H17: 0.22629187 | I17: 0.049368941 | J17: 0.0034462803
A18: 13 | B18: Lansing, MI | C18: Midwest | D18: 6 | E18: 17547.96 | F18: 0 | G18: 0.0071233351 | H18: 0.2652616 | I18: 0.08039681 | J18: 0
A19: 14 | B19: Woodbury, MN | C19: Midwest | D19: 6 | E19: 2660.01 | F19: 0.046992305 | G19: 0.16823245 | H19: 1.2531908 | I19: 0.26390878 | J19: 0
A20: 15 | B20: Fort Collins, CO | C20: Rocky Mountains | D20: 7 | E20: 34440.5 | F20: 0.22067043 | G20: 0.037455902 | H20: 0.41339847 | I20: 0.059035148 | J20: 0.051091012
... A143: 902 | B143: Washington, DC | C143: Mid Atlantic | D143: 8 | E143: 16724.8 | F143: 0.10678753 | G143: 0 | H143: 0.34535241 | I143: 0.083117885 | J143: 0
A144: Grand Total | E144: 3126634.6 | F144: 0.048202179 | G144: 0.027089891 | H144: 0.38833002 | I144: 0.13228692 | J144: 0.017228905

Sheet YoY Analysis
A1: Year-over-Year Analysis - MTD & YTD
A2: *This document is strictly confidential and may not be shared or redistributed in any form without written consent from the corporate office.
A4: Current Month | B4: =MAX(Table_Sales_Data[[#All],[Sales_Date]]) -> 46143
A5: Beginning of Year | B5: =DATE(YEAR(B4),1,1) -> 46023
A6: Beginning of Previous Year | B6: =DATE(YEAR(B4)-1,1,1) -> 45658
D7: =YEAR(B4)-1 -> 2025 | F7: =YEAR(B4) -> 2026 | H7: YoY Analysis
A8: Location ID | B8: City_State | C8: Region | D8: =DATE(YEAR(B4)-1,MONTH(B4),DAY(B4)) -> 45778 | E8: YTD | F8: =DATE(YEAR(B4),MONTH(B4),DAY(B4)) -> 46143 | G8: YTD | H8: MTD | I8: YTD
A9: 2 | B9: Novi, MI | C9: Midwest | D9: =SUMIFS(Table_Sales_Data[[#All],[Total Sales]],Table_Sales_Data[[#All],[Sales_Date]],'YoY Analysis'!$D$8,Table_Sales_Data[[#All],[Location ID]],'YoY Analysis'!A9) -> 25672.96 | E9: =SUMIFS(Table_Sales_Data[[#All],[Total Sales]],Table_Sales_Data[[#All],[Sales_Date]],"<="&'YoY Analysis'!$D$8,Table_Sales_Data[[#All],[Sales_Date]],">="&'YoY Analysis'!$B$6,Table_Sales_Data[[#All],[Location ID]],'YoY Analysis'!A9) -> 336041.94 | F9: =SUMIFS(Table_Sales_Data[[#All],[Total Sales]],Table_Sales_Data[[#All],[Sales_Date]],'YoY Analysis'!$F$8,Table_Sales_Data[[#All],[Location ID]],'YoY Analysis'!A9) -> 20831.05 | G9: =SUMIFS(Table_Sales_Data[[#All],[Total Sales]],Table_Sales_Data[[#All],[Sales_Date]],"<="&'YoY Analysis'!$F$8,Table_Sales_Data[[#All],[Sales_Date]],">="&'YoY Analysis'!$B$5,Table_Sales_Data[[#All],[Location ID]],'YoY Analysis'!A9) -> 345916.77 | H9: =IFERROR((F9-D9)/D9,0) -> -0.1885996 | I9: =IFERROR((G9-E9)/E9,0) -> 0.029385707
A10: 4 | B10: Huntsville, AL | C10: South | D10: =SUMIFS(Table_Sales_Data[[#All],[Total Sales]],Table_Sales_Data[[#All],[Sales_Date]],'YoY Analysis'!$D$8,Table_Sales_Data[[#All],[Location ID]],'YoY Analysis'!A10) -> 61691.9 | E10: =SUMIFS(Table_Sales_Data[[#All],[Total Sales]],Table_Sales_Data[[#All],[Sales_Date]],"<="&'YoY Analysis'!$D$8,Table_Sales_Data[[#All],[Sales_Date]],">="&'YoY Analysis'!$B$6,Table_Sales_Data[[#All],[Location ID]],'YoY Analysis'!A10) -> 280465.95 | F10: =SUMIFS(Table_Sales_Data[[#All],[Total Sales]],Table_Sales_Data[[#All],[Sales_Date]],'YoY Analysis'!$F$8,Table_Sales_Data[[#All],[Location ID]],'YoY Analysis'!A10) -> 28046.01 | G10: =SUMIFS(Table_Sales_Data[[#All],[Total Sales]],Table_Sales_Data[[#All],[Sales_Date]],"<="&'YoY Analysis'!$F$8,Table_Sales_Data[[#All],[Sales_Date]],">="&'YoY Analysis'!$B$5,Table_Sales_Data[[#All],[Location ID]],'YoY Analysis'!A10) -> 180523.32 | H10: =IFERROR((F10-D10)/D10,0) -> -0.54538586 | I10: =IFERROR((G10-E10)/E10,0) -> -0.35634497
A11: 6 | B11: Grand Rapids, MI | C11: Midwest | D11: =SUMIFS(Table_Sales_Data[[#All],[Total Sales]],Table_Sales_Data[[#All],[Sales_Date]],'YoY Analysis'!$D$8,Table_Sales_Data[[#All],[Location ID]],'YoY Analysis'!A11) -> 20520.95 | E11: =SUMIFS(Table_Sales_Data[[#All],[Total Sales]],Table_Sales_Data[[#All],[Sales_Date]],"<="&'YoY Analysis'!$D$8,Table_Sales_Data[[#All],[Sales_Date]],">="&'YoY Analysis'!$B$6,Table_Sales_Data[[#All],[Location ID]],'YoY Analysis'!A11) -> 415964.65 | F11: =SUMIFS(Table_Sales_Data[[#All],[Total Sales]],Table_Sales_Data[[#All],[Sales_Date]],'YoY Analysis'!$F$8,Table_Sales_Data[[#All],[Location ID]],'YoY Analysis'!A11) -> 11918.66 | G11: =SUMIFS(Table_Sales_Data[[#All],[Total Sales]],Table_Sales_Data[[#All],[Sales_Date]],"<="&'YoY Analysis'!$F$8,Table_Sales_Data[[#All],[Sales_Date]],">="&'YoY Analysis'!$B$5,Table_Sales_Data[[#All],[Location ID]],'YoY Analysis'!A11) -> 384795.61 | H11: =IFERROR((F11-D11)/D11,0) -> -0.41919551 | I11: =IFERROR((G11-E11)/E11,0) -> -0.074931944
A12: 7 | B12: Ann Arbor, MI | C12: Midwest | D12: =SUMIFS(Table_Sales_Data[[#All],[Total Sales]],Table_Sales_Data[[#All],[Sales_Date]],'YoY Analysis'!$D$8,Table_Sales_Data[[#All],[Location ID]],'YoY Analysis'!A12) -> 10923.84 | E12: =SUMIFS(Table_Sales_Data[[#All],[Total Sales]],Table_Sales_Data[[#All],[Sales_Date]],"<="&'YoY Analysis'!$D$8,Table_Sales_Data[[#All],[Sales_Date]],">="&'YoY Analysis'!$B$6,Table_Sales_Data[[#All],[Location ID]],'YoY Analysis'!A12) -> 312051.55 | F12: =SUMIFS(Table_Sales_Data[[#All],[Total Sales]],Table_Sales_Data[[#All],[Sales_Date]],'YoY Analysis'!$F$8,Table_Sales_Data[[#All],[Location ID]],'YoY Analysis'!A12) -> 17898.97 | G12: =SUMIFS(Table_Sales_Data[[#All],[Total Sales]],Table_Sales_Data[[#All],[Sales_Date]],"<="&'YoY Analysis'!$F$8,Table_Sales_Data[[#All],[Sales_Date]],">="&'YoY Analysis'!$B$5,Table_Sales_Data[[#All],[Location ID]],'YoY Analysis'!A12) -> 357769.86 | H12: =IFERROR((F12-D12)/D12,0) -> 0.63852363 | I12: =IFERROR((G12-E12)/E12,0) -> 0.14650884
A13: 8 | B13: Shelby Twp, MI | C13: Midwest | D13: =SUMIFS(Table_Sales_Data[[#All],[Total Sales]],Table_Sales_Data[[#All],[Sales_Date]],'YoY Analysis'!$D$8,Table_Sales_Data[[#All],[Location ID]],'YoY Analysis'!A13) -> 17320.98 | E13: =SUMIFS(Table_Sales_Data[[#All],[Total Sales]],Table_Sales_Data[[#All],[Sales_Date]],"<="&'YoY Analysis'!$D$8,Table_Sales_Data[[#All],[Sales_Date]],">="&'YoY Analysis'!$B$6,Table_Sales_Data[[#All],[Location ID]],'YoY Analysis'!A13) -> 442287 | F13: =SUMIFS(Table_Sales_Data[[#All],[Total Sales]],Table_Sales_Data[[#All],[Sales_Date]],'YoY Analysis'!$F$8,Table_Sales_Data[[#All],[Location ID]],'YoY Analysis'!A13) -> 24155.52 | G13: =SUMIFS(Table_Sales_Data[[#All],[Total Sales]],Table_Sales_Data[[#All],[Sales_Date]],"<="&'YoY Analysis'!$F$8,Table_Sales_Data[[#All],[Sales_Date]],">="&'YoY Analysis'!$B$5,Table_Sales_Data[[#All],[Location ID]],'YoY Analysis'!A13) -> 483229.46 | H13: =IFERROR((F13-D13)/D13,0) -> 0.3945816 | I13: =IFERROR((G13-E13)/E13,0) -> 0.092569892
A14: 9 | B14: Grand Junction, CO | C14: Rocky Mountains | D14: =SUMIFS(Table_Sales_Data[[#All],[Total Sales]],Table_Sales_Data[[#All],[Sales_Date]],'YoY Analysis'!$D$8,Table_Sales_Data[[#All],[Location ID]],'YoY Analysis'!A14) -> 32837.47 | E14: =SUMIFS(Table_Sales_Data[[#All],[Total Sales]],Table_Sales_Data[[#All],[Sales_Date]],"<="&'YoY Analysis'!$D$8,Table_Sales_Data[[#All],[Sales_Date]],">="&'YoY Analysis'!$B$6,Table_Sales_Data[[#All],[Location ID]],'YoY Analysis'!A14) -> 284613.03 | F14: =SUMIFS(Table_Sales_Data[[#All],[Total Sales]],Table_Sales_Data[[#All],[Sales_Date]],'YoY Analysis'!$F$8,Table_Sales_Data[[#All],[Location ID]],'YoY Analysis'!A14) -> 34175.9 | G14: =SUMIFS(Table_Sales_Data[[#All],[Total Sales]],Table_Sales_Data[[#All],[Sales_Date]],"<="&'YoY Analysis'!$F$8,Table_Sales_Data[[#All],[Sales_Date]],">="&'YoY Analysis'!$B$5,Table_Sales_Data[[#All],[Location ID]],'YoY Analysis'!A14) -> 300493.64 | H14: =IFERROR((F14-D14)/D14,0) -> 0.04075923 | I14: =IFERROR((G14-E14)/E14,0) -> 0.055797199
A15: 10 | B15: Holland, MI | C15: Midwest | D15: =SUMIFS(Table_Sales_Data[[#All],[Total Sales]],Table_Sales_Data[[#All],[Sales_Date]],'YoY Analysis'!$D$8,Table_Sales_Data[[#All],[Location ID]],'YoY Analysis'!A15) -> 13266.73 | E15: =SUMIFS(Table_Sales_Data[[#All],[Total Sales]],Table_Sales_Data[[#All],[Sales_Date]],"<="&'YoY Analysis'!$D$8,Table_Sales_Data[[#All],[Sales_Date]],">="&'YoY Analysis'!$B$6,Table_Sales_Data[[#All],[Location ID]],'YoY Analysis'!A15) -> 426077.29 | F15: =SUMIFS(Table_Sales_Data[[#All],[Total Sales]],Table_Sales_Data[[#All],[Sales_Date]],'YoY Analysis'!$F$8,Table_Sales_Data[[#All],[Location ID]],'YoY Analysis'!A15) -> 13042.23 | G15: =SUMIFS(Table_Sales_Data[[#All],[Total Sales]],Table_Sales_Data[[#All],[Sales_Date]],"<="&'YoY Analysis'!$F$8,Table_Sales_Data[[#All],[Sales_Date]],">="&'YoY Analysis'!$B$5,Table_Sales_Data[[#All],[Location ID]],'YoY Analysis'!A15) -> 422975.9 | H15: =IFERROR((F15-D15)/D15,0) -> -0.01692203 | I15: =IFERROR((G15-E15)/E15,0) -> -0.0072789376
A16: 11 | B16: Kalamazoo, MI | C16: Midwest | D16: =SUMIFS(Table_Sales_Data[[#All],[Total Sales]],Table_Sales_Data[[#All],[Sales_Date]],'YoY Analysis'!$D$8,Table_Sales_Data[[#All],[Location ID]],'YoY Analysis'!A16) -> 20438.01 | E16: =SUMIFS(Table_Sales_Data[[#All],[Total Sales]],Table_Sales_Data[[#All],[Sales_Date]],"<="&'YoY Analysis'!$D$8,Table_Sales_Data[[#All],[Sales_Date]],">="&'YoY Analysis'!$B$6,Table_Sales_Data[[#All],[Location ID]],'YoY Analysis'!A16) -> 440518.97 | F16: =SUMIFS(Table_Sales_Data[[#All],[Total Sales]],Table_Sales_Data[[#All],[Sales_Date]],'YoY Analysis'!$F$8,Table_Sales_Data[[#All],[Location ID]],'YoY Analysis'!A16) -> 14339.68 | G16: =SUMIFS(Table_Sales_Data[[#All],[Total Sales]],Table_Sales_Data[[#All],[Sales_Date]],"<="&'YoY Analysis'!$F$8,Table_Sales_Data[[#All],[Sales_Date]],">="&'YoY Analysis'!$B$5,Table_Sales_Data[[#All],[Location ID]],'YoY Analysis'!A16) -> 495857.26 | H16: =IFERROR((F16-D16)/D16,0) -> -0.29838179 | I16: =IFERROR((G16-E16)/E16,0) -> 0.12562067
A17: 12 | B17: Rochester Hills, MI | C17: Midwest | D17: =SUMIFS(Table_Sales_Data[[#All],[Total Sales]],Table_Sales_Data[[#All],[Sales_Date]],'YoY Analysis'!$D$8,Table_Sales_Data[[#All],[Location ID]],'YoY Analysis'!A17) -> 14182.23 | E17: =SUMIFS(Table_Sales_Data[[#All],[Total Sales]],Table_Sales_Data[[#All],[Sales_Date]],"<="&'YoY Analysis'!$D$8,Table_Sales_Data[[#All],[Sales_Date]],">="&'YoY Analysis'!$B$6,Table_Sales_Data[[#All],[Location ID]],'YoY Analysis'!A17) -> 366316.58 | F17: =SUMIFS(Table_Sales_Data[[#All],[Total Sales]],Table_Sales_Data[[#All],[Sales_Date]],'YoY Analysis'!$F$8,Table_Sales_Data[[#All],[Location ID]],'YoY Analysis'!A17) -> 10015.63 | G17: =SUMIFS(Table_Sales_Data[[#All],[Total Sales]],Table_Sales_Data[[#All],[Sales_Date]],"<="&'YoY Analysis'!$F$8,Table_Sales_Data[[#All],[Sales_Date]],">="&'YoY Analysis'!$B$5,Table_Sales_Data[[#All],[Location ID]],'YoY Analysis'!A17) -> 333903.87 | H17: =IFERROR((F17-D17)/D17,0) -> -0.29379019 | I17: =IFERROR((G17-E17)/E17,0) -> -0.088482782
A18: 13 | B18: Lansing, MI | C18: Midwest | D18: =SUMIFS(Table_Sales_Data[[#All],[Total Sales]],Table_Sales_Data[[#All],[Sales_Date]],'YoY Analysis'!$D$8,Table_Sales_Data[[#All],[Location ID]],'YoY Analysis'!A18) -> 29631.29 | E18: =SUMIFS(Table_Sales_Data[[#All],[Total Sales]],Table_Sales_Data[[#All],[Sales_Date]],"<="&'YoY Analysis'!$D$8,Table_Sales_Data[[#All],[Sales_Date]],">="&'YoY Analysis'!$B$6,Table_Sales_Data[[#All],[Location ID]],'YoY Analysis'!A18) -> 435562.39 | F18: =SUMIFS(Table_Sales_Data[[#All],[Total Sales]],Table_Sales_Data[[#All],[Sales_Date]],'YoY Analysis'!$F$8,Table_Sales_Data[[#All],[Location ID]],'YoY Analysis'!A18) -> 23738.56 | G18: =SUMIFS(Table_Sales_Data[[#All],[Total Sales]],Table_Sales_Data[[#All],[Sales_Date]],"<="&'YoY Analysis'!$F$8,Table_Sales_Data[[#All],[Sales_Date]],">="&'YoY Analysis'!$B$5,Table_Sales_Data[[#All],[Location ID]],'YoY Analysis'!A18) -> 404705.46 | H18: =IFERROR((F18-D18)/D18,0) -> -0.19886849 | I18: =IFERROR((G18-E18)/E18,0) -> -0.070843881
A19: 14 | B19: Woodbury, MN | C19: Midwest | D19: =SUMIFS(Table_Sales_Data[[#All],[Total Sales]],Table_Sales_Data[[#All],[Sales_Date]],'YoY Analysis'!$D$8,Table_Sales_Data[[#All],[Location ID]],'YoY Analysis'!A19) -> 15988.23 | E19: =SUMIFS(Table_Sales_Data[[#All],[Total Sales]],Table_Sales_Data[[#All],[Sales_Date]],"<="&'YoY Analysis'!$D$8,Table_Sales_Data[[#All],[Sales_Date]],">="&'YoY Analysis'!$B$6,Table_Sales_Data[[#All],[Location ID]],'YoY Analysis'!A19) -> 335100.62 | F19: =SUMIFS(Table_Sales_Data[[#All],[Total Sales]],Table_Sales_Data[[#All],[Sales_Date]],'YoY Analysis'!$F$8,Table_Sales_Data[[#All],[Location ID]],'YoY Analysis'!A19) -> 7268.01 | G19: =SUMIFS(Table_Sales_Data[[#All],[Total Sales]],Table_Sales_Data[[#All],[Sales_Date]],"<="&'YoY Analysis'!$F$8,Table_Sales_Data[[#All],[Sales_Date]],">="&'YoY Analysis'!$B$5,Table_Sales_Data[[#All],[Location ID]],'YoY Analysis'!A19) -> 304310.35 | H19: =IFERROR((F19-D19)/D19,0) -> -0.54541497 | I19: =IFERROR((G19-E19)/E19,0) -> -0.091883656
A20: 15 | B20: Fort Collins, CO | C20: Rocky Mountains | D20: =SUMIFS(Table_Sales_Data[[#All],[Total Sales]],Table_Sales_Data[[#All],[Sales_Date]],'YoY Analysis'!$D$8,Table_Sales_Data[[#All],[Location ID]],'YoY Analysis'!A20) -> 60093.69 | E20: =SUMIFS(Table_Sales_Data[[#All],[Total Sales]],Table_Sales_Data[[#All],[Sales_Date]],"<="&'YoY Analysis'!$D$8,Table_Sales_Data[[#All],[Sales_Date]],">="&'YoY Analysis'!$B$6,Table_Sales_Data[[#All],[Location ID]],'YoY Analysis'!A20) -> 570487.12 | F20: =SUMIFS(Table_Sales_Data[[#All],[Total Sales]],Table_Sales_Data[[#All],[Sales_Date]],'YoY Analysis'!$F$8,Table_Sales_Data[[#All],[Location ID]],'YoY Analysis'!A20) -> 61360.95 | G20: =SUMIFS(Table_Sales_Data[[#All],[Total Sales]],Table_Sales_Data[[#All],[Sales_Date]],"<="&'YoY Analysis'!$F$8,Table_Sales_Data[[#All],[Sales_Date]],">="&'YoY Analysis'!$B$5,Table_Sales_Data[[#All],[Location ID]],'YoY Analysis'!A20) -> 448362.23 | H20: =IFERROR((F20-D20)/D20,0) -> 0.021088071 | I20: =IFERROR((G20-E20)/E20,0) -> -0.21407125
... A148: 902 | B148: Washington, DC | C148: Mid Atlantic | D148: =SUMIFS(Table_Sales_Data[[#All],[Total Sales]],Table_Sales_Data[[#All],[Sales_Date]],'YoY Analysis'!$D$8,Table_Sales_Data[[#All],[Location ID]],'YoY Analysis'!A148) -> 27622.24 | E148: =SUMIFS(Table_Sales_Data[[#All],[Total Sales]],Table_Sales_Data[[#All],[Sales_Date]],"<="&'YoY Analysis'!$D$8,Table_Sales_Data[[#All],[Sales_Date]],">="&'YoY Analysis'!$B$6,Table_Sales_Data[[#All],[Location ID]],'YoY Analysis'!A148) -> 186810.82 | F148: =SUMIFS(Table_Sales_Data[[#All],[Total Sales]],Table_Sales_Data[[#All],[Sales_Date]],'YoY Analysis'!$F$8,Table_Sales_Data[[#All],[Location ID]],'YoY Analysis'!A148) -> 25676.88 | G148: =SUMIFS(Table_Sales_Data[[#All],[Total Sales]],Table_Sales_Data[[#All],[Sales_Date]],"<="&'YoY Analysis'!$F$8,Table_Sales_Data[[#All],[Sales_Date]],">="&'YoY Analysis'!$B$5,Table_Sales_Data[[#All],[Location ID]],'YoY Analysis'!A148) -> 184741.76 | H148: =IFERROR((F148-D148)/D148,0) -> -0.070427308 | I148: =IFERROR((G148-E148)/E148,0) -> -0.011075697
A149: Grand Total | D149: =SUM(D9:D148) -> 5196940 | E149: =SUM(E9:E148) -> 55449235 | F149: =SUM(F9:F148) -> 5066436.2 | G149: =SUM(G9:G148) -> 56547069 | H149: =(F149-D149)/D149 -> -0.025111662 | I149: =(G149-E149)/E149 -> 0.019798894

Sheet Raw Reports (No Pivot Table)-->

Sheet Total Sales by Month_raw
A1: Total Sales by Location by Date
A2: *This document is strictly confidential and may not be shared or redistributed in any form without written consent from the corporate office.
A4: Sum of Total Sales | F4: Years | G4: Sales_Date
F5: 2023 | G5: 2024 | H5: 2025 | I5: 2026 | N5: 2026 Total
A6: Location ID | B6: City_State | C6: Region | D6: # of Sims | E6: Royalty % | I6: Jan | J6: Feb | K6: Mar | L6: Apr | M6: May
A7: 2 | B7: Novi, MI | C7: Midwest | D7: 5 | E7: 6 | F7: 649140.12 | G7: 622105.56 | H7: 615190.81 | I7: 135182.95 | J7: 78656.61 | K7: 71484.68 | L7: 39761.48 | M7: 20831.05 | N7: 345916.77
A8: 4 | B8: Huntsville, AL | C8: South | D8: 5 | E8: 6 | F8: 552143.26 | G8: 534697.4 | H8: 556953.33 | I8: 65699.18 | J8: 39950.35 | K8: 27450.74 | L8: 19377.04 | M8: 28046.01 | N8: 180523.32
A9: 6 | B9: Grand Rapids, MI | C9: Midwest | D9: 6 | E9: 6 | F9: 912130.77 | G9: 707186.72 | H9: 632528.89 | I9: 106215.06 | J9: 127057.04 | K9: 87232.51 | L9: 52372.34 | M9: 11918.66 | N9: 384795.61
A10: 7 | B10: Ann Arbor, MI | C10: Midwest | D10: 6 | E10: 6 | F10: 458482.74 | G10: 376475.25 | H10: 508990.01 | I10: 139544.23 | J10: 90580.45 | K10: 76427.84 | L10: 33318.37 | M10: 17898.97 | N10: 357769.86
A11: 8 | B11: Shelby Twp, MI | C11: Midwest | D11: 6 | E11: 6 | F11: 813062.42 | G11: 723540.51 | H11: 803888.63 | I11: 161515.39 | J11: 115081.59 | K11: 117676.66 | L11: 64800.3 | M11: 24155.52 | N11: 483229.46
A12: 9 | B12: Grand Junction, CO | C12: Rocky Mountains | D12: 5 | E12: 6 | F12: 393696.76 | G12: 484489.45 | H12: 579043.65 | I12: 117146.85 | J12: 66991.09 | K12: 42749.3 | L12: 39430.5 | M12: 34175.9 | N12: 300493.64
A13: 10 | B13: Holland, MI | C13: Midwest | D13: 6 | E13: 6 | F13: 731678.9 | G13: 646981.99 | H13: 691066.44 | I13: 122747.93 | J13: 131775.65 | K13: 100373.79 | L13: 55036.3 | M13: 13042.23 | N13: 422975.9
A14: 11 | B14: Kalamazoo, MI | C14: Midwest | D14: 6 | E14: 6 | F14: 727827.25 | G14: 672687.92 | H14: 763572.52 | I14: 159387.02 | J14: 140882.27 | K14: 122053.96 | L14: 59194.33 | M14: 14339.68 | N14: 495857.26
A15: 12 | B15: Rochester Hills, MI | C15: Midwest | D15: 6 | E15: 6 | F15: 689477.23 | G15: 584674.29 | H15: 564363.58 | I15: 138190.15 | J15: 79041.37 | K15: 73576.86 | L15: 33079.86 | M15: 10015.63 | N15: 333903.87
A16: 13 | B16: Lansing, MI | C16: Midwest | D16: 6 | E16: 6 | F16: 806910.02 | G16: 765165.57 | H16: 791750.72 | I16: 121710.34 | J16: 109160.81 | K16: 95766.62 | L16: 54329.13 | M16: 23738.56 | N16: 404705.46
A17: 14 | B17: Woodbury, MN | C17: Midwest | D17: 6 | E17: 4.5 | F17: 661148.09 | G17: 543123.17 | H17: 618247.15 | I17: 102293.66 | J17: 76900.79 | K17: 75371.55 | L17: 42476.34 | M17: 7268.01 | N17: 304310.35
A18: 15 | B18: Fort Collins, CO | C18: Rocky Mountains | D18: 7 | E18: 6 | F18: 1205504.8 | G18: 1054459.3 | H18: 1102766.4 | I18: 130332.39 | J18: 102785.14 | K18: 94532.68 | L18: 59351.07 | M18: 61360.95 | N18: 448362.23
... A25: 22 | B25: Champlin, MN | C25: Midwest | D25: 6 | E25: 4.5 | F25: 660460.36 | G25: 533955.13 | H25: 576536.1 | I25: 106896.67 | J25: 78359.03 | K25: 82310.02 | L25: 42805.02 | M25: 12682.49 | N25: 323053.23
A26: 23 | B26: Wexford, PA | C26: Mid Atlantic | F26: 644310.93 | G26: 671547.34 | H26: 420805.73
A27: 24 | B27: Garnet Valley, PA | C27: Mid Atlantic | F27: 776757.97 | G27: 766644.86 | H27: 807148.29 | I27: 151090.12 | J27: 137352.01 | K27: 81814.92 | L27: 34805.2 | M27: 40239.91 | N27: 445302.16
A28: 25 | B28: Richmond, VA | C28: South | D28: 6 | E28: 6 | F28: 676847.56 | G28: 645884.02 | H28: 709339.03 | I28: 102457.11 | J28: 82543.78 | K28: 49870.74 | L28: 23726.67 | M28: 40384.08 | N28: 298982.38
A29: 26 | B29: Glenview, IL | C29: Midwest | D29: 8 | E29: 6 | F29: 848776.45 | G29: 711892.65 | H29: 663027.37 | I29: 121718.1 | J29: 103245.1 | K29: 86455.53 | L29: 47201.61 | M29: 20392.29 | N29: 379012.63
A30: 27 | B30: Royal Oak, MI | C30: Midwest | D30: 6 | E30: 6 | F30: 936404.71 | G30: 846491.99 | H30: 845979.91 | I30: 110781.66 | J30: 152709.37 | K30: 106986.19 | L30: 57539.5 | M30: 25609.38 | N30: 453626.1
A31: 28 | B31: Madison, WI | C31: Midwest | D31: 8 | E31: 6 | F31: 654733.05 | G31: 503363.96 | H31: 496268.48 | I31: 115128.9 | J31: 94599.2 | K31: 77981.48 | L31: 43693.98 | M31: 11982.26 | N31: 343385.82
A32: 29 | B32: Middleton, WI | C32: Midwest | D32: 7 | E32: 6 | F32: 609074.5 | G32: 530080.78 | H32: 597572.44 | I32: 107749.55 | J32: 88086.37 | K32: 73510.86 | L32: 41134.95 | M32: 15386.4 | N32: 325868.13
A33: 30 | B33: Mequon, WI | C33: Midwest | D33: 7 | E33: 6 | F33: 642614.93 | G33: 583072.46 | H33: 624828.31 | I33: 98964.19 | J33: 127313.64 | K33: 77990.64 | L33: 70940.12 | M33: 29462.84 | N33: 404671.43
A34: 31 | B34: Greenwood Village, CO | C34: Rocky Mountains | D34: 7 | E34: 6 | F34: 1279896.9 | G34: 1225561.5 | H34: 1061116.6 | I34: 136174.64 | J34: 95039.19 | K34: 83426.63 | L34: 66090.33 | M34: 69303.04 | N34: 450033.83
A35: 32 | B35: Canton, MI | C35: Midwest | D35: 7 | E35: 7 | F35: 810150.57 | G35: 736553.43 | H35: 792402.77 | I35: 169043.64 | J35: 123562.68 | K35: 115159.44 | L35: 49689.96 | M35: 22378.89 | N35: 479834.61
A36: 33 | B36: Lincoln, RI | C36: Northeast | D36: 6 | E36: 6 | F36: 867756.39 | G36: 687299.41 | H36: 750551.87 | I36: 152700.6 | J36: 124084.91 | K36: 123474.56 | L36: 39452.81 | M36: 27655.91 | N36: 467368.79
A37: 34 | B37: Woodhaven, MI | C37: Midwest | D37: 7 | E37: 6 | F37: 840742.69 | G37: 808203.74 | H37: 941365.17 | I37: 210506.28 | J37: 134444.25 | K37: 125871.27 | L37: 72696.8 | M37: 38130.62 | N37: 581649.22
A38: 35 | B38: Schaumburg, IL | C38: Midwest | D38: 9 | E38: 6 | F38: 767090.64 | G38: 749129.25 | H38: 917942.66 | I38: 172196.53 | J38: 144008.04 | K38: 101347.33 | L38: 63078.08 | M38: 25462.24 | N38: 506092.22
A39: 36 | B39: Leawood, KS | C39: Midwest | D39: 7 | E39: 6 | F39: 803505.77 | G39: 825834.09 | H39: 983769.19 | I39: 153549.67 | J39: 107838.81 | K39: 81700.49 | L39: 54639.25 | M39: 39912.73 | N39: 437640.95
A40: 37 | B40: Easton, PA | C40: Mid Atlantic | F40: 513065.83 | G40: 619333.75 | H40: 703556.15 | I40: 146257.77 | J40: 126804.45 | K40: 88067.31 | L40: 28786.5 | M40: 28523.49 | N40: 418439.52
A41: 38 | B41: Downers Grove, IL | C41: Midwest | D41: 8 | E41: 6 | F41: 620760.16 | G41: 548238.53 | H41: 650529.01 | I41: 112205.42 | J41: 141183.76 | K41: 72376.95 | L41: 36280.37 | M41: 8464.83 | N41: 370511.33
A42: 39 | B42: Hilton Head, SC | C42: South | D42: 6 | E42: 6 | F42: 734997.03 | G42: 480653.92
A43: 40 | B43: Burlington, MA | C43: Northeast | D43: 7 | E43: 6 | F43: 1311718.3 | G43: 1292097.8 | H43: 1355665 | I43: 182102.58 | J43: 180958.42 | K43: 175090.51 | L43: 63694.95 | M43: 59893.26 | N43: 661739.72
A44: 41 | B44: South Charlotte, SC | C44: South | D44: 5 | E44: 6 | F44: 602936.12 | G44: 648502.31 | H44: 623265.63 | I44: 63894.39 | J44: 52478.01 | K44: 30420.38 | L44: 23742.71 | M44: 48374.26 | N44: 218909.75
A45: 42 | B45: Orland Park, IL | C45: Midwest | D45: 8 | E45: 6 | F45: 734866.4 | G45: 595840.92 | H45: 592897.34 | I45: 130827.34 | J45: 120959.38 | K45: 97318.61 | L45: 63585.3 | M45: 22490.4 | N45: 435181.03
A46: 43 | B46: Kildeer, IL | C46: Midwest | D46: 10 | E46: 6 | F46: 759278.55 | G46: 679566.66 | H46: 770923.3 | I46: 150945.42 | J46: 122030.02 | K46: 96763.41 | L46: 60608.26 | M46: 24159.45 | N46: 454506.56
A47: 44 | B47: Columbus, OH | C47: Midwest | D47: 7 | E47: 6 | F47: 1062440 | G47: 925791.68 | H47: 1070740.7 | I47: 151005.76 | J47: 135123.85 | K47: 109393.23 | L47: 53914.96 | M47: 59569.22 | N47: 509007.02
...

Sheet Category Sales_raw
A1: Category Sales by Location for Month
A2: *This document is strictly confidential and may not be shared or redistributed in any form without written consent from the corporate office.
A4: Years | B4: 2026
A5: Sales_Date | B5: May
E7: Categories
A8: Location ID | B8: City_State | C8: Region | D8: # of Sims | E8: Golf | F8: League | G8: Lessons | H8: Beverage | I8: Food | J8: Merchandise | K8: Service Charge | L8: Total Sales
A9: 2 | B9: Novi, MI | C9: Midwest | D9: 5 | E9: 15094.85 | F9: 1080 | G9: 0 | H9: 3470.48 | I9: 994.72 | J9: 191 | K9: 0 | L9: 20831.05
A10: 4 | B10: Huntsville, AL | C10: South | D10: 5 | E10: 18847.77 | F10: 1735 | G10: 0 | H10: 5752.8 | I10: 1710.44 | J10: 0 | K10: 0 | L10: 28046.01
A11: 6 | B11: Grand Rapids, MI | C11: Midwest | D11: 6 | E11: 7851.65 | F11: 45 | G11: 1240 | H11: 2265 | I11: 512.02 | J11: 4.99 | K11: 0 | L11: 11918.66
A12: 7 | B12: Ann Arbor, MI | C12: Midwest | D12: 6 | E12: 12919.96 | F12: 0 | G12: 0 | H12: 2943.5 | I12: 905 | J12: 1130.51 | K12: 0 | L12: 17898.97
A13: 8 | B13: Shelby Twp, MI | C13: Midwest | D13: 6 | E13: 12339.97 | F13: 1490 | G13: 577.5 | H13: 8447.12 | I13: 1253.96 | J13: 46.97 | K13: 0 | L13: 24155.52
A14: 9 | B14: Grand Junction, CO | C14: Rocky Mountains | D14: 5 | E14: 19783.29 | F14: 4600 | G14: 0 | H14: 8438.21 | I14: 1327.1 | J14: 27.3 | K14: 0 | L14: 34175.9
A15: 10 | B15: Holland, MI | C15: Midwest | D15: 6 | E15: 8838.99 | F15: 0 | G15: 475 | H15: 2860.25 | I15: 843 | J15: 24.99 | K15: 0 | L15: 13042.23
A16: 11 | B16: Kalamazoo, MI | C16: Midwest | D16: 6 | E16: 7180.08 | F16: 560 | G16: 1230 | H16: 4168.68 | I16: 728 | J16: 472.92 | K16: 0 | L16: 14339.68
A17: 12 | B17: Rochester Hills, MI | C17: Midwest | D17: 6 | E17: 7689.45 | F17: 180 | G17: 0 | H17: 1740.06 | I17: 379.62 | J17: 26.5 | K17: 0 | L17: 10015.63
A18: 13 | B18: Lansing, MI | C18: Midwest | D18: 6 | E18: 17547.96 | F18: 0 | G18: 125 | H18: 4654.8 | I18: 1410.8 | J18: 0 | K18: 0 | L18: 23738.56
A19: 14 | B19: Woodbury, MN | C19: Midwest | D19: 6 | E19: 2660.01 | F19: 125 | G19: 447.5 | H19: 3333.5 | I19: 702 | J19: 0 | K19: 0 | L19: 7268.01
A20: 15 | B20: Fort Collins, CO | C20: Rocky Mountains | D20: 7 | E20: 34440.5 | F20: 7600 | G20: 1290 | H20: 14237.65 | I20: 2033.2 | J20: 1759.6 | K20: 0 | L20: 61360.95
... A143: 902 | B143: Washington, DC | C143: Mid Atlantic | D143: 8 | E143: 16724.8 | F143: 1786 | G143: 0 | H143: 5775.95 | I143: 1390.13 | J143: 0 | K143: 0 | L143: 25676.88
A144: Grand Total | E144: 3126634.6 | F144: 150710.6 | G144: 84700.19 | H144: 1214166.1 | I144: 413612.85 | J144: 53868.49 | K144: 22743.42 | L144: 5066436.2

Sheet Lesson Sales by Month_raw
A1: Lesson Sales by Location for Month
A2: *This document is strictly confidential and may not be shared or redistributed in any form without written consent from the corporate office.
A4: Lessons | D4: Years | E4: Sales_Date
D5: 2023 | E5: 2024 | F5: 2025 | G5: 2026 | L5: 2026 Total
A6: Location ID | B6: City_State | C6: Region | G6: Jan | H6: Feb | I6: Mar | J6: Apr | K6: May
A7: 2 | B7: Novi, MI | C7: Midwest | D7: -468.5 | E7: 0 | F7: 0 | G7: 0 | H7: 0 | I7: 0 | J7: 0 | K7: 0 | L7: 0
A8: 4 | B8: Huntsville, AL | C8: South | D8: 18310.82 | E8: 7940 | F8: 1919.64 | G8: 0 | H8: 0 | I8: 0 | J8: 0 | K8: 0 | L8: 0
A9: 6 | B9: Grand Rapids, MI | C9: Midwest | D9: 26212.8 | E9: 18619.06 | F9: 10565.5 | G9: 1414 | H9: 170 | I9: 530 | J9: 455 | K9: 1240 | L9: 3809
A10: 7 | B10: Ann Arbor, MI | C10: Midwest | D10: 0 | E10: 0 | F10: 250 | G10: 0 | H10: 0 | I10: 0 | J10: 0 | K10: 0 | L10: 0
A11: 8 | B11: Shelby Twp, MI | C11: Midwest | D11: 5457 | E11: 925 | F11: 6365 | G11: 435 | H11: 1030 | I11: 555 | J11: 1290 | K11: 577.5 | L11: 3887.5
A12: 9 | B12: Grand Junction, CO | C12: Rocky Mountains | D12: 0 | E12: 0 | F12: 0 | G12: 0 | H12: 0 | I12: 0 | J12: 0 | K12: 0 | L12: 0
A13: 10 | B13: Holland, MI | C13: Midwest | D13: 8317.09 | E13: 6978 | F13: 13778.24 | G13: 285 | H13: 260 | I13: 1760 | J13: 1220 | K13: 475 | L13: 4000
A14: 11 | B14: Kalamazoo, MI | C14: Midwest | D14: 17210 | E14: 19414.99 | F14: 20064.06 | G14: 3314 | H14: 2300 | I14: 3530 | J14: 1875 | K14: 1230 | L14: 12249
A15: 12 | B15: Rochester Hills, MI | C15: Midwest | D15: 7721.21 | E15: 3330 | F15: 645 | G15: 0 | H15: 0 | I15: 0 | J15: 0 | K15: 0 | L15: 0
A16: 13 | B16: Lansing, MI | C16: Midwest | D16: 12370 | E16: 12835 | F16: 23235 | G16: 2515 | H16: 650 | I16: 3395 | J16: 1100 | K16: 125 | L16: 7785
A17: 14 | B17: Woodbury, MN | C17: Midwest | D17: 4190 | E17: 2570 | F17: 12033.65 | G17: 3787.08 | H17: 1711.25 | I17: 671.25 | J17: 1266.25 | K17: 447.5 | L17: 7883.33
A18: 15 | B18: Fort Collins, CO | C18: Rocky Mountains | D18: 59508.43 | E18: 37936.95 | F18: 20485 | G18: 2515 | H18: 2284 | I18: 1050 | J18: 775 | K18: 1290 | L18: 7914
... A25: 22 | B25: Champlin, MN | C25: Midwest | D25: 6580 | E25: 9585 | F25: 6666 | G25: 893 | H25: 1173 | I25: 537.5 | J25: 447.5 | K25: 268.75 | L25: 3319.75
A26: 23 | B26: Wexford, PA | C26: Mid Atlantic | D26: 18525 | E26: 18095 | F26: 9415
A27: 24 | B27: Garnet Valley, PA | C27: Mid Atlantic | D27: 18521.88 | E27: 23450 | F27: 14060 | G27: 1082 | H27: 2800 | I27: 4514 | J27: 3660 | K27: 670 | L27: 12726
A28: 25 | B28: Richmond, VA | C28: South | D28: 6051.53 | E28: 821.71 | F28: 328 | G28: 0 | H28: 48 | I28: 0 | J28: 0 | K28: 0 | L28: 48
A29: 26 | B29: Glenview, IL | C29: Midwest | D29: 1890 | E29: 3410 | F29: 3495 | G29: 0 | H29: 0 | I29: 0 | J29: 0 | K29: 0 | L29: 0
A30: 27 | B30: Royal Oak, MI | C30: Midwest | D30: 3015 | E30: 4134 | F30: 4835 | G30: 0 | H30: 165 | I30: 145 | J30: 325 | K30: 325 | L30: 960
A31: 28 | B31: Madison, WI | C31: Midwest | D31: 6719.11 | E31: 2336.43 | F31: 1788 | G31: 0 | H31: 0 | I31: 0 | J31: 0 | K31: 0 | L31: 0
A32: 29 | B32: Middleton, WI | C32: Midwest | D32: 6606.68 | E32: 2380 | F32: 1140 | G32: 0 | H32: 0 | I32: 0 | J32: 0 | K32: 0 | L32: 0
A33: 30 | B33: Mequon, WI | C33: Midwest | D33: 8735 | E33: 10715.87 | F33: 13260.56 | G33: 1880 | H33: 1975 | I33: 893 | J33: 1062 | K33: 2179 | L33: 7989
A34: 31 | B34: Greenwood Village, CO | C34: Rocky Mountains | D34: 22381 | E34: 24412.2 | F34: 1850 | G34: 0 | H34: 0 | I34: 0 | J34: 0 | K34: 0 | L34: 0
A35: 32 | B35: Canton, MI | C35: Midwest | D35: 6550 | E35: 3630 | F35: 95 | G35: 0 | H35: 0 | I35: 0 | J35: 0 | K35: 0 | L35: 0
A36: 33 | B36: Lincoln, RI | C36: Northeast | D36: 0 | E36: 0 | F36: 2430 | G36: 360 | H36: 180 | I36: 270 | J36: 180 | K36: 0 | L36: 990
A37: 34 | B37: Woodhaven, MI | C37: Midwest | D37: 22530 | E37: 31275 | F37: 8790 | G37: 0 | H37: 0 | I37: 0 | J37: 0 | K37: 0 | L37: 0
A38: 35 | B38: Schaumburg, IL | C38: Midwest | D38: 14600 | E38: 50 | F38: 0 | G38: 0 | H38: 0 | I38: 0 | J38: 0 | K38: 0 | L38: 0
... A41: 38 | B41: Downers Grove, IL | C41: Midwest | D41: 3773 | E41: 1930 | F41: 10300 | G41: 915 | H41: 1050 | I41: 945 | J41: 0 | K41: 0 | L41: 2910
A42: 39 | B42: Hilton Head, SC | C42: South | D42: 1150 | E42: 0
A43: 40 | B43: Burlington, MA | C43: Northeast | D43: 9010 | E43: 13265 | F43: 5415 | G43: 165 | H43: 125 | I43: 500 | J43: 125 | K43: 0 | L43: 915
A44: 41 | B44: South Charlotte, SC | C44: South | D44: 8837.41 | E44: 12553.7 | F44: 17405.76 | G44: 1729.98 | H44: 1724.98 | I44: 795 | J44: 1439.99 | K44: 1625 | L44: 7314.95
A45: 42 | B45: Orland Park, IL | C45: Midwest | D45: 8514.82 | E45: 0 | F45: 0 | G45: 0 | H45: 0 | I45: 0 | J45: 0 | K45: 0 | L45: 0
A46: 43 | B46: Kildeer, IL | C46: Midwest | D46: 3721 | E46: 24692 | F46: 6531 | G46: 0 | H46: 0 | I46: 0 | J46: 0 | K46: 0 | L46: 0
A47: 44 | B47: Columbus, OH | C47: Midwest | D47: 4120 | E47: 15150 | F47: 9375 | G47: 0 | H47: 0 | I47: 0 | J47: 0 | K47: 0 | L47: 0
A48: 45 | B48: Powell, OH | C48: Midwest | E48: 3650 | F48: 3050 | G48: 0 | H48: 0 | I48: 0 | J48: 0 | K48: 0 | L48: 0
A49: 47 | B49: Commack, NY | C49: Mid Atlantic | D49: 21737.03 | E49: 102857 | F49: 118353.07 | G49: 10984.5 | H49: 11769.22 | I49: 11316.14 | J49: 7872.96 | K49: 9596.49 | L49: 51539.31
...

Sheet Category Avg by # Sims_raw
A1: Category Avg by # Sims
A2: *This document is strictly confidential and may not be shared or redistributed in any form without written consent from the corporate office.
A4: Years | B4: 2026
A5: Sales_Date | B5: May
E7: Average Per Sim
A8: Location ID | B8: City_State | C8: Region | D8: # of Sims | E8: Golf | F8: League | G8: Lessons | H8: Beverage | I8: Food | J8: Merchandise | K8: Total Sales
A9: 2 | B9: Novi, MI | C9: Midwest | D9: 5 | E9: 3018.97 | F9: 216 | G9: 0 | H9: 694.096 | I9: 198.944 | J9: 38.2 | K9: 4166.21
A10: 4 | B10: Huntsville, AL | C10: South | D10: 5 | E10: 3769.554 | F10: 347 | G10: 0 | H10: 1150.56 | I10: 342.088 | J10: 0 | K10: 5609.202
A11: 6 | B11: Grand Rapids, MI | C11: Midwest | D11: 6 | E11: 1308.6083 | F11: 7.5 | G11: 206.66667 | H11: 377.5 | I11: 85.336667 | J11: 0.83166667 | K11: 1986.4433
A12: 7 | B12: Ann Arbor, MI | C12: Midwest | D12: 6 | E12: 2153.3267 | F12: 0 | G12: 0 | H12: 490.58333 | I12: 150.83333 | J12: 188.41833 | K12: 2983.1617
A13: 8 | B13: Shelby Twp, MI | C13: Midwest | D13: 6 | E13: 2056.6617 | F13: 248.33333 | G13: 96.25 | H13: 1407.8533 | I13: 208.99333 | J13: 7.8283333 | K13: 4025.92
A14: 9 | B14: Grand Junction, CO | C14: Rocky Mountains | D14: 5 | E14: 3956.658 | F14: 920 | G14: 0 | H14: 1687.642 | I14: 265.42 | J14: 5.46 | K14: 6835.18
A15: 10 | B15: Holland, MI | C15: Midwest | D15: 6 | E15: 1473.165 | F15: 0 | G15: 79.166667 | H15: 476.70833 | I15: 140.5 | J15: 4.165 | K15: 2173.705
A16: 11 | B16: Kalamazoo, MI | C16: Midwest | D16: 6 | E16: 1196.68 | F16: 93.333333 | G16: 205 | H16: 694.78 | I16: 121.33333 | J16: 78.82 | K16: 2389.9467
A17: 12 | B17: Rochester Hills, MI | C17: Midwest | D17: 6 | E17: 1281.575 | F17: 30 | G17: 0 | H17: 290.01 | I17: 63.27 | J17: 4.4166667 | K17: 1669.2717
A18: 13 | B18: Lansing, MI | C18: Midwest | D18: 6 | E18: 2924.66 | F18: 0 | G18: 20.833333 | H18: 775.8 | I18: 235.13333 | J18: 0 | K18: 3956.4267
A19: 14 | B19: Woodbury, MN | C19: Midwest | D19: 6 | E19: 443.335 | F19: 20.833333 | G19: 74.583333 | H19: 555.58333 | I19: 117 | J19: 0 | K19: 1211.335
